

[ERROR 2019-08-12 14:04:56,421] module: exception, process: 15327, thread: 140303547352832
Internal Server Error: /admin/
Traceback (most recent call last):
  File "/opt/openwisp2/env/lib/python3.5/site-packages/django/core/handlers/exception.py", line 35, in inner
    response = get_response(request)
  File "/opt/openwisp2/env/lib/python3.5/site-packages/django/core/handlers/base.py", line 113, in _get_response
    resolver_match = resolver.resolve(request.path_info)
  File "/opt/openwisp2/env/lib/python3.5/site-packages/django/urls/resolvers.py", line 498, in resolve
    for pattern in self.url_patterns:
  File "/opt/openwisp2/env/lib/python3.5/site-packages/django/utils/functional.py", line 36, in __get__
    res = instance.__dict__[self.name] = self.func(instance)
  File "/opt/openwisp2/env/lib/python3.5/site-packages/django/urls/resolvers.py", line 540, in url_patterns
    patterns = getattr(self.urlconf_module, "urlpatterns", self.urlconf_module)
  File "/opt/openwisp2/env/lib/python3.5/site-packages/django/utils/functional.py", line 36, in __get__
    res = instance.__dict__[self.name] = self.func(instance)
  File "/opt/openwisp2/env/lib/python3.5/site-packages/django/urls/resolvers.py", line 533, in urlconf_module
    return import_module(self.urlconf_name)
  File "/opt/openwisp2/env/lib/python3.5/importlib/__init__.py", line 126, in import_module
    return _bootstrap._gcd_import(name[level:], package, level)
  File "<frozen importlib._bootstrap>", line 986, in _gcd_import
  File "<frozen importlib._bootstrap>", line 969, in _find_and_load
  File "<frozen importlib._bootstrap>", line 958, in _find_and_load_unlocked
  File "<frozen importlib._bootstrap>", line 673, in _load_unlocked
  File "<frozen importlib._bootstrap_external>", line 665, in exec_module
  File "<frozen importlib._bootstrap>", line 222, in _call_with_frames_removed
  File "./openwisp2/urls.py", line 19, in <module>
    url(r'^', include('openwisp_radius.urls', namespace='freeradius')),
  File "/opt/openwisp2/env/lib/python3.5/site-packages/django/urls/conf.py", line 34, in include
    urlconf_module = import_module(urlconf_module)
  File "/opt/openwisp2/env/lib/python3.5/importlib/__init__.py", line 126, in import_module
    return _bootstrap._gcd_import(name[level:], package, level)
  File "<frozen importlib._bootstrap>", line 986, in _gcd_import
  File "<frozen importlib._bootstrap>", line 969, in _find_and_load
  File "<frozen importlib._bootstrap>", line 958, in _find_and_load_unlocked
  File "<frozen importlib._bootstrap>", line 673, in _load_unlocked
  File "<frozen importlib._bootstrap_external>", line 665, in exec_module
  File "<frozen importlib._bootstrap>", line 222, in _call_with_frames_removed
  File "/opt/openwisp2/env/lib/python3.5/site-packages/openwisp_radius/urls.py", line 4, in <module>
    from .api import urls as api
  File "/opt/openwisp2/env/lib/python3.5/site-packages/openwisp_radius/api/urls.py", line 3, in <module>
    from . import views
  File "/opt/openwisp2/env/lib/python3.5/site-packages/openwisp_radius/api/views.py", line 10, in <module>
    from django_freeradius.api.views import AccountingView as BaseAccountingView
  File "/opt/openwisp2/env/lib/python3.5/site-packages/django_freeradius/api/views.py", line 15, in <module>
    from .serializers import RadiusAccountingSerializer, RadiusBatchSerializer, RadiusPostAuthSerializer
  File "/opt/openwisp2/env/lib/python3.5/site-packages/django_freeradius/api/serializers.py", line 7, in <module>
    RadiusPostAuth = swapper.load_model('django_freeradius', 'RadiusPostAuth')
  File "/opt/openwisp2/env/lib/python3.5/site-packages/swapper/__init__.py", line 94, in load_model
    "Could not find {name}!".format(name=join(app_label, model))
django.core.exceptions.ImproperlyConfigured: Could not find django_freeradius.RadiusPostAuth!


[ERROR 2019-08-12 14:04:56,680] module: exception, process: 15327, thread: 140303547352832
Internal Server Error: /admin/
Traceback (most recent call last):
  File "/opt/openwisp2/env/lib/python3.5/site-packages/django/core/handlers/exception.py", line 35, in inner
    response = get_response(request)
  File "/opt/openwisp2/env/lib/python3.5/site-packages/django/core/handlers/base.py", line 113, in _get_response
    resolver_match = resolver.resolve(request.path_info)
  File "/opt/openwisp2/env/lib/python3.5/site-packages/django/urls/resolvers.py", line 498, in resolve
    for pattern in self.url_patterns:
  File "/opt/openwisp2/env/lib/python3.5/site-packages/django/utils/functional.py", line 36, in __get__
    res = instance.__dict__[self.name] = self.func(instance)
  File "/opt/openwisp2/env/lib/python3.5/site-packages/django/urls/resolvers.py", line 540, in url_patterns
    patterns = getattr(self.urlconf_module, "urlpatterns", self.urlconf_module)
  File "/opt/openwisp2/env/lib/python3.5/site-packages/django/utils/functional.py", line 36, in __get__
    res = instance.__dict__[self.name] = self.func(instance)
  File "/opt/openwisp2/env/lib/python3.5/site-packages/django/urls/resolvers.py", line 533, in urlconf_module
    return import_module(self.urlconf_name)
  File "/opt/openwisp2/env/lib/python3.5/importlib/__init__.py", line 126, in import_module
    return _bootstrap._gcd_import(name[level:], package, level)
  File "<frozen importlib._bootstrap>", line 986, in _gcd_import
  File "<frozen importlib._bootstrap>", line 969, in _find_and_load
  File "<frozen importlib._bootstrap>", line 958, in _find_and_load_unlocked
  File "<frozen importlib._bootstrap>", line 673, in _load_unlocked
  File "<frozen importlib._bootstrap_external>", line 665, in exec_module
  File "<frozen importlib._bootstrap>", line 222, in _call_with_frames_removed
  File "./openwisp2/urls.py", line 19, in <module>
    url(r'^', include('openwisp_radius.urls', namespace='freeradius')),
  File "/opt/openwisp2/env/lib/python3.5/site-packages/django/urls/conf.py", line 34, in include
    urlconf_module = import_module(urlconf_module)
  File "/opt/openwisp2/env/lib/python3.5/importlib/__init__.py", line 126, in import_module
    return _bootstrap._gcd_import(name[level:], package, level)
  File "<frozen importlib._bootstrap>", line 986, in _gcd_import
  File "<frozen importlib._bootstrap>", line 969, in _find_and_load
  File "<frozen importlib._bootstrap>", line 958, in _find_and_load_unlocked
  File "<frozen importlib._bootstrap>", line 673, in _load_unlocked
  File "<frozen importlib._bootstrap_external>", line 665, in exec_module
  File "<frozen importlib._bootstrap>", line 222, in _call_with_frames_removed
  File "/opt/openwisp2/env/lib/python3.5/site-packages/openwisp_radius/urls.py", line 4, in <module>
    from .api import urls as api
  File "/opt/openwisp2/env/lib/python3.5/site-packages/openwisp_radius/api/urls.py", line 3, in <module>
    from . import views
  File "/opt/openwisp2/env/lib/python3.5/site-packages/openwisp_radius/api/views.py", line 10, in <module>
    from django_freeradius.api.views import AccountingView as BaseAccountingView
  File "/opt/openwisp2/env/lib/python3.5/site-packages/django_freeradius/api/views.py", line 15, in <module>
    from .serializers import RadiusAccountingSerializer, RadiusBatchSerializer, RadiusPostAuthSerializer
  File "/opt/openwisp2/env/lib/python3.5/site-packages/django_freeradius/api/serializers.py", line 7, in <module>
    RadiusPostAuth = swapper.load_model('django_freeradius', 'RadiusPostAuth')
  File "/opt/openwisp2/env/lib/python3.5/site-packages/swapper/__init__.py", line 94, in load_model
    "Could not find {name}!".format(name=join(app_label, model))
django.core.exceptions.ImproperlyConfigured: Could not find django_freeradius.RadiusPostAuth!

During handling of the above exception, another exception occurred:

Traceback (most recent call last):
  File "/opt/openwisp2/env/lib/python3.5/site-packages/django/core/handlers/exception.py", line 35, in inner
    response = get_response(request)
  File "/opt/openwisp2/env/lib/python3.5/site-packages/django/utils/deprecation.py", line 95, in __call__
    response = self.get_response(request)
  File "/opt/openwisp2/env/lib/python3.5/site-packages/django/core/handlers/exception.py", line 37, in inner
    response = response_for_exception(request, exc)
  File "/opt/openwisp2/env/lib/python3.5/site-packages/django/core/handlers/exception.py", line 87, in response_for_exception
    response = handle_uncaught_exception(request, get_resolver(get_urlconf()), sys.exc_info())
  File "/opt/openwisp2/env/lib/python3.5/site-packages/django/core/handlers/exception.py", line 125, in handle_uncaught_exception
    callback, param_dict = resolver.resolve_error_handler(500)
  File "/opt/openwisp2/env/lib/python3.5/site-packages/django/urls/resolvers.py", line 553, in resolve_error_handler
    callback = getattr(self.urlconf_module, 'handler%s' % view_type, None)
  File "/opt/openwisp2/env/lib/python3.5/site-packages/django/utils/functional.py", line 36, in __get__
    res = instance.__dict__[self.name] = self.func(instance)
  File "/opt/openwisp2/env/lib/python3.5/site-packages/django/urls/resolvers.py", line 533, in urlconf_module
    return import_module(self.urlconf_name)
  File "/opt/openwisp2/env/lib/python3.5/importlib/__init__.py", line 126, in import_module
    return _bootstrap._gcd_import(name[level:], package, level)
  File "<frozen importlib._bootstrap>", line 986, in _gcd_import
  File "<frozen importlib._bootstrap>", line 969, in _find_and_load
  File "<frozen importlib._bootstrap>", line 958, in _find_and_load_unlocked
  File "<frozen importlib._bootstrap>", line 673, in _load_unlocked
  File "<frozen importlib._bootstrap_external>", line 665, in exec_module
  File "<frozen importlib._bootstrap>", line 222, in _call_with_frames_removed
  File "./openwisp2/urls.py", line 19, in <module>
    url(r'^', include('openwisp_radius.urls', namespace='freeradius')),
  File "/opt/openwisp2/env/lib/python3.5/site-packages/django/urls/conf.py", line 34, in include
    urlconf_module = import_module(urlconf_module)
  File "/opt/openwisp2/env/lib/python3.5/importlib/__init__.py", line 126, in import_module
    return _bootstrap._gcd_import(name[level:], package, level)
  File "<frozen importlib._bootstrap>", line 986, in _gcd_import
  File "<frozen importlib._bootstrap>", line 969, in _find_and_load
  File "<frozen importlib._bootstrap>", line 958, in _find_and_load_unlocked
  File "<frozen importlib._bootstrap>", line 673, in _load_unlocked
  File "<frozen importlib._bootstrap_external>", line 665, in exec_module
  File "<frozen importlib._bootstrap>", line 222, in _call_with_frames_removed
  File "/opt/openwisp2/env/lib/python3.5/site-packages/openwisp_radius/urls.py", line 4, in <module>
    from .api import urls as api
  File "/opt/openwisp2/env/lib/python3.5/site-packages/openwisp_radius/api/urls.py", line 3, in <module>
    from . import views
  File "/opt/openwisp2/env/lib/python3.5/site-packages/openwisp_radius/api/views.py", line 10, in <module>
    from django_freeradius.api.views import AccountingView as BaseAccountingView
  File "/opt/openwisp2/env/lib/python3.5/site-packages/django_freeradius/api/views.py", line 15, in <module>
    from .serializers import RadiusAccountingSerializer, RadiusBatchSerializer, RadiusPostAuthSerializer
  File "/opt/openwisp2/env/lib/python3.5/site-packages/django_freeradius/api/serializers.py", line 7, in <module>
    RadiusPostAuth = swapper.load_model('django_freeradius', 'RadiusPostAuth')
  File "/opt/openwisp2/env/lib/python3.5/site-packages/swapper/__init__.py", line 94, in load_model
    "Could not find {name}!".format(name=join(app_label, model))
django.core.exceptions.ImproperlyConfigured: Could not find django_freeradius.RadiusPostAuth!


[ERROR 2019-08-12 14:04:56,916] module: exception, process: 15327, thread: 140303547352832
Internal Server Error: /admin/
Traceback (most recent call last):
  File "/opt/openwisp2/env/lib/python3.5/site-packages/django/core/handlers/exception.py", line 35, in inner
    response = get_response(request)
  File "/opt/openwisp2/env/lib/python3.5/site-packages/django/core/handlers/base.py", line 113, in _get_response
    resolver_match = resolver.resolve(request.path_info)
  File "/opt/openwisp2/env/lib/python3.5/site-packages/django/urls/resolvers.py", line 498, in resolve
    for pattern in self.url_patterns:
  File "/opt/openwisp2/env/lib/python3.5/site-packages/django/utils/functional.py", line 36, in __get__
    res = instance.__dict__[self.name] = self.func(instance)
  File "/opt/openwisp2/env/lib/python3.5/site-packages/django/urls/resolvers.py", line 540, in url_patterns
    patterns = getattr(self.urlconf_module, "urlpatterns", self.urlconf_module)
  File "/opt/openwisp2/env/lib/python3.5/site-packages/django/utils/functional.py", line 36, in __get__
    res = instance.__dict__[self.name] = self.func(instance)
  File "/opt/openwisp2/env/lib/python3.5/site-packages/django/urls/resolvers.py", line 533, in urlconf_module
    return import_module(self.urlconf_name)
  File "/opt/openwisp2/env/lib/python3.5/importlib/__init__.py", line 126, in import_module
    return _bootstrap._gcd_import(name[level:], package, level)
  File "<frozen importlib._bootstrap>", line 986, in _gcd_import
  File "<frozen importlib._bootstrap>", line 969, in _find_and_load
  File "<frozen importlib._bootstrap>", line 958, in _find_and_load_unlocked
  File "<frozen importlib._bootstrap>", line 673, in _load_unlocked
  File "<frozen importlib._bootstrap_external>", line 665, in exec_module
  File "<frozen importlib._bootstrap>", line 222, in _call_with_frames_removed
  File "./openwisp2/urls.py", line 19, in <module>
    url(r'^', include('openwisp_radius.urls', namespace='freeradius')),
  File "/opt/openwisp2/env/lib/python3.5/site-packages/django/urls/conf.py", line 34, in include
    urlconf_module = import_module(urlconf_module)
  File "/opt/openwisp2/env/lib/python3.5/importlib/__init__.py", line 126, in import_module
    return _bootstrap._gcd_import(name[level:], package, level)
  File "<frozen importlib._bootstrap>", line 986, in _gcd_import
  File "<frozen importlib._bootstrap>", line 969, in _find_and_load
  File "<frozen importlib._bootstrap>", line 958, in _find_and_load_unlocked
  File "<frozen importlib._bootstrap>", line 673, in _load_unlocked
  File "<frozen importlib._bootstrap_external>", line 665, in exec_module
  File "<frozen importlib._bootstrap>", line 222, in _call_with_frames_removed
  File "/opt/openwisp2/env/lib/python3.5/site-packages/openwisp_radius/urls.py", line 4, in <module>
    from .api import urls as api
  File "/opt/openwisp2/env/lib/python3.5/site-packages/openwisp_radius/api/urls.py", line 3, in <module>
    from . import views
  File "/opt/openwisp2/env/lib/python3.5/site-packages/openwisp_radius/api/views.py", line 10, in <module>
    from django_freeradius.api.views import AccountingView as BaseAccountingView
  File "/opt/openwisp2/env/lib/python3.5/site-packages/django_freeradius/api/views.py", line 15, in <module>
    from .serializers import RadiusAccountingSerializer, RadiusBatchSerializer, RadiusPostAuthSerializer
  File "/opt/openwisp2/env/lib/python3.5/site-packages/django_freeradius/api/serializers.py", line 7, in <module>
    RadiusPostAuth = swapper.load_model('django_freeradius', 'RadiusPostAuth')
  File "/opt/openwisp2/env/lib/python3.5/site-packages/swapper/__init__.py", line 94, in load_model
    "Could not find {name}!".format(name=join(app_label, model))
django.core.exceptions.ImproperlyConfigured: Could not find django_freeradius.RadiusPostAuth!

During handling of the above exception, another exception occurred:

Traceback (most recent call last):
  File "/opt/openwisp2/env/lib/python3.5/site-packages/django/core/handlers/exception.py", line 35, in inner
    response = get_response(request)
  File "/opt/openwisp2/env/lib/python3.5/site-packages/django/utils/deprecation.py", line 95, in __call__
    response = self.get_response(request)
  File "/opt/openwisp2/env/lib/python3.5/site-packages/django/core/handlers/exception.py", line 37, in inner
    response = response_for_exception(request, exc)
  File "/opt/openwisp2/env/lib/python3.5/site-packages/django/core/handlers/exception.py", line 87, in response_for_exception
    response = handle_uncaught_exception(request, get_resolver(get_urlconf()), sys.exc_info())
  File "/opt/openwisp2/env/lib/python3.5/site-packages/django/core/handlers/exception.py", line 125, in handle_uncaught_exception
    callback, param_dict = resolver.resolve_error_handler(500)
  File "/opt/openwisp2/env/lib/python3.5/site-packages/django/urls/resolvers.py", line 553, in resolve_error_handler
    callback = getattr(self.urlconf_module, 'handler%s' % view_type, None)
  File "/opt/openwisp2/env/lib/python3.5/site-packages/django/utils/functional.py", line 36, in __get__
    res = instance.__dict__[self.name] = self.func(instance)
  File "/opt/openwisp2/env/lib/python3.5/site-packages/django/urls/resolvers.py", line 533, in urlconf_module
    return import_module(self.urlconf_name)
  File "/opt/openwisp2/env/lib/python3.5/importlib/__init__.py", line 126, in import_module
    return _bootstrap._gcd_import(name[level:], package, level)
  File "<frozen importlib._bootstrap>", line 986, in _gcd_import
  File "<frozen importlib._bootstrap>", line 969, in _find_and_load
  File "<frozen importlib._bootstrap>", line 958, in _find_and_load_unlocked
  File "<frozen importlib._bootstrap>", line 673, in _load_unlocked
  File "<frozen importlib._bootstrap_external>", line 665, in exec_module
  File "<frozen importlib._bootstrap>", line 222, in _call_with_frames_removed
  File "./openwisp2/urls.py", line 19, in <module>
    url(r'^', include('openwisp_radius.urls', namespace='freeradius')),
  File "/opt/openwisp2/env/lib/python3.5/site-packages/django/urls/conf.py", line 34, in include
    urlconf_module = import_module(urlconf_module)
  File "/opt/openwisp2/env/lib/python3.5/importlib/__init__.py", line 126, in import_module
    return _bootstrap._gcd_import(name[level:], package, level)
  File "<frozen importlib._bootstrap>", line 986, in _gcd_import
  File "<frozen importlib._bootstrap>", line 969, in _find_and_load
  File "<frozen importlib._bootstrap>", line 958, in _find_and_load_unlocked
  File "<frozen importlib._bootstrap>", line 673, in _load_unlocked
  File "<frozen importlib._bootstrap_external>", line 665, in exec_module
  File "<frozen importlib._bootstrap>", line 222, in _call_with_frames_removed
  File "/opt/openwisp2/env/lib/python3.5/site-packages/openwisp_radius/urls.py", line 4, in <module>
    from .api import urls as api
  File "/opt/openwisp2/env/lib/python3.5/site-packages/openwisp_radius/api/urls.py", line 3, in <module>
    from . import views
  File "/opt/openwisp2/env/lib/python3.5/site-packages/openwisp_radius/api/views.py", line 10, in <module>
    from django_freeradius.api.views import AccountingView as BaseAccountingView
  File "/opt/openwisp2/env/lib/python3.5/site-packages/django_freeradius/api/views.py", line 15, in <module>
    from .serializers import RadiusAccountingSerializer, RadiusBatchSerializer, RadiusPostAuthSerializer
  File "/opt/openwisp2/env/lib/python3.5/site-packages/django_freeradius/api/serializers.py", line 7, in <module>
    RadiusPostAuth = swapper.load_model('django_freeradius', 'RadiusPostAuth')
  File "/opt/openwisp2/env/lib/python3.5/site-packages/swapper/__init__.py", line 94, in load_model
    "Could not find {name}!".format(name=join(app_label, model))
django.core.exceptions.ImproperlyConfigured: Could not find django_freeradius.RadiusPostAuth!

During handling of the above exception, another exception occurred:

Traceback (most recent call last):
  File "/opt/openwisp2/env/lib/python3.5/site-packages/django/core/handlers/exception.py", line 35, in inner
    response = get_response(request)
  File "/opt/openwisp2/env/lib/python3.5/site-packages/django/utils/deprecation.py", line 95, in __call__
    response = self.get_response(request)
  File "/opt/openwisp2/env/lib/python3.5/site-packages/django/core/handlers/exception.py", line 37, in inner
    response = response_for_exception(request, exc)
  File "/opt/openwisp2/env/lib/python3.5/site-packages/django/core/handlers/exception.py", line 87, in response_for_exception
    response = handle_uncaught_exception(request, get_resolver(get_urlconf()), sys.exc_info())
  File "/opt/openwisp2/env/lib/python3.5/site-packages/django/core/handlers/exception.py", line 125, in handle_uncaught_exception
    callback, param_dict = resolver.resolve_error_handler(500)
  File "/opt/openwisp2/env/lib/python3.5/site-packages/django/urls/resolvers.py", line 553, in resolve_error_handler
    callback = getattr(self.urlconf_module, 'handler%s' % view_type, None)
  File "/opt/openwisp2/env/lib/python3.5/site-packages/django/utils/functional.py", line 36, in __get__
    res = instance.__dict__[self.name] = self.func(instance)
  File "/opt/openwisp2/env/lib/python3.5/site-packages/django/urls/resolvers.py", line 533, in urlconf_module
    return import_module(self.urlconf_name)
  File "/opt/openwisp2/env/lib/python3.5/importlib/__init__.py", line 126, in import_module
    return _bootstrap._gcd_import(name[level:], package, level)
  File "<frozen importlib._bootstrap>", line 986, in _gcd_import
  File "<frozen importlib._bootstrap>", line 969, in _find_and_load
  File "<frozen importlib._bootstrap>", line 958, in _find_and_load_unlocked
  File "<frozen importlib._bootstrap>", line 673, in _load_unlocked
  File "<frozen importlib._bootstrap_external>", line 665, in exec_module
  File "<frozen importlib._bootstrap>", line 222, in _call_with_frames_removed
  File "./openwisp2/urls.py", line 19, in <module>
    url(r'^', include('openwisp_radius.urls', namespace='freeradius')),
  File "/opt/openwisp2/env/lib/python3.5/site-packages/django/urls/conf.py", line 34, in include
    urlconf_module = import_module(urlconf_module)
  File "/opt/openwisp2/env/lib/python3.5/importlib/__init__.py", line 126, in import_module
    return _bootstrap._gcd_import(name[level:], package, level)
  File "<frozen importlib._bootstrap>", line 986, in _gcd_import
  File "<frozen importlib._bootstrap>", line 969, in _find_and_load
  File "<frozen importlib._bootstrap>", line 958, in _find_and_load_unlocked
  File "<frozen importlib._bootstrap>", line 673, in _load_unlocked
  File "<frozen importlib._bootstrap_external>", line 665, in exec_module
  File "<frozen importlib._bootstrap>", line 222, in _call_with_frames_removed
  File "/opt/openwisp2/env/lib/python3.5/site-packages/openwisp_radius/urls.py", line 4, in <module>
    from .api import urls as api
  File "/opt/openwisp2/env/lib/python3.5/site-packages/openwisp_radius/api/urls.py", line 3, in <module>
    from . import views
  File "/opt/openwisp2/env/lib/python3.5/site-packages/openwisp_radius/api/views.py", line 10, in <module>
    from django_freeradius.api.views import AccountingView as BaseAccountingView
  File "/opt/openwisp2/env/lib/python3.5/site-packages/django_freeradius/api/views.py", line 15, in <module>
    from .serializers import RadiusAccountingSerializer, RadiusBatchSerializer, RadiusPostAuthSerializer
  File "/opt/openwisp2/env/lib/python3.5/site-packages/django_freeradius/api/serializers.py", line 7, in <module>
    RadiusPostAuth = swapper.load_model('django_freeradius', 'RadiusPostAuth')
  File "/opt/openwisp2/env/lib/python3.5/site-packages/swapper/__init__.py", line 94, in load_model
    "Could not find {name}!".format(name=join(app_label, model))
django.core.exceptions.ImproperlyConfigured: Could not find django_freeradius.RadiusPostAuth!


[ERROR 2019-08-12 14:04:57,349] module: exception, process: 15327, thread: 140303547352832
Internal Server Error: /admin/
Traceback (most recent call last):
  File "/opt/openwisp2/env/lib/python3.5/site-packages/django/core/handlers/exception.py", line 35, in inner
    response = get_response(request)
  File "/opt/openwisp2/env/lib/python3.5/site-packages/django/core/handlers/base.py", line 113, in _get_response
    resolver_match = resolver.resolve(request.path_info)
  File "/opt/openwisp2/env/lib/python3.5/site-packages/django/urls/resolvers.py", line 498, in resolve
    for pattern in self.url_patterns:
  File "/opt/openwisp2/env/lib/python3.5/site-packages/django/utils/functional.py", line 36, in __get__
    res = instance.__dict__[self.name] = self.func(instance)
  File "/opt/openwisp2/env/lib/python3.5/site-packages/django/urls/resolvers.py", line 540, in url_patterns
    patterns = getattr(self.urlconf_module, "urlpatterns", self.urlconf_module)
  File "/opt/openwisp2/env/lib/python3.5/site-packages/django/utils/functional.py", line 36, in __get__
    res = instance.__dict__[self.name] = self.func(instance)
  File "/opt/openwisp2/env/lib/python3.5/site-packages/django/urls/resolvers.py", line 533, in urlconf_module
    return import_module(self.urlconf_name)
  File "/opt/openwisp2/env/lib/python3.5/importlib/__init__.py", line 126, in import_module
    return _bootstrap._gcd_import(name[level:], package, level)
  File "<frozen importlib._bootstrap>", line 986, in _gcd_import
  File "<frozen importlib._bootstrap>", line 969, in _find_and_load
  File "<frozen importlib._bootstrap>", line 958, in _find_and_load_unlocked
  File "<frozen importlib._bootstrap>", line 673, in _load_unlocked
  File "<frozen importlib._bootstrap_external>", line 665, in exec_module
  File "<frozen importlib._bootstrap>", line 222, in _call_with_frames_removed
  File "./openwisp2/urls.py", line 19, in <module>
    url(r'^', include('openwisp_radius.urls', namespace='freeradius')),
  File "/opt/openwisp2/env/lib/python3.5/site-packages/django/urls/conf.py", line 34, in include
    urlconf_module = import_module(urlconf_module)
  File "/opt/openwisp2/env/lib/python3.5/importlib/__init__.py", line 126, in import_module
    return _bootstrap._gcd_import(name[level:], package, level)
  File "<frozen importlib._bootstrap>", line 986, in _gcd_import
  File "<frozen importlib._bootstrap>", line 969, in _find_and_load
  File "<frozen importlib._bootstrap>", line 958, in _find_and_load_unlocked
  File "<frozen importlib._bootstrap>", line 673, in _load_unlocked
  File "<frozen importlib._bootstrap_external>", line 665, in exec_module
  File "<frozen importlib._bootstrap>", line 222, in _call_with_frames_removed
  File "/opt/openwisp2/env/lib/python3.5/site-packages/openwisp_radius/urls.py", line 4, in <module>
    from .api import urls as api
  File "/opt/openwisp2/env/lib/python3.5/site-packages/openwisp_radius/api/urls.py", line 3, in <module>
    from . import views
  File "/opt/openwisp2/env/lib/python3.5/site-packages/openwisp_radius/api/views.py", line 10, in <module>
    from django_freeradius.api.views import AccountingView as BaseAccountingView
  File "/opt/openwisp2/env/lib/python3.5/site-packages/django_freeradius/api/views.py", line 15, in <module>
    from .serializers import RadiusAccountingSerializer, RadiusBatchSerializer, RadiusPostAuthSerializer
  File "/opt/openwisp2/env/lib/python3.5/site-packages/django_freeradius/api/serializers.py", line 7, in <module>
    RadiusPostAuth = swapper.load_model('django_freeradius', 'RadiusPostAuth')
  File "/opt/openwisp2/env/lib/python3.5/site-packages/swapper/__init__.py", line 94, in load_model
    "Could not find {name}!".format(name=join(app_label, model))
django.core.exceptions.ImproperlyConfigured: Could not find django_freeradius.RadiusPostAuth!

During handling of the above exception, another exception occurred:

Traceback (most recent call last):
  File "/opt/openwisp2/env/lib/python3.5/site-packages/django/core/handlers/exception.py", line 35, in inner
    response = get_response(request)
  File "/opt/openwisp2/env/lib/python3.5/site-packages/django/utils/deprecation.py", line 95, in __call__
    response = self.get_response(request)
  File "/opt/openwisp2/env/lib/python3.5/site-packages/django/core/handlers/exception.py", line 37, in inner
    response = response_for_exception(request, exc)
  File "/opt/openwisp2/env/lib/python3.5/site-packages/django/core/handlers/exception.py", line 87, in response_for_exception
    response = handle_uncaught_exception(request, get_resolver(get_urlconf()), sys.exc_info())
  File "/opt/openwisp2/env/lib/python3.5/site-packages/django/core/handlers/exception.py", line 125, in handle_uncaught_exception
    callback, param_dict = resolver.resolve_error_handler(500)
  File "/opt/openwisp2/env/lib/python3.5/site-packages/django/urls/resolvers.py", line 553, in resolve_error_handler
    callback = getattr(self.urlconf_module, 'handler%s' % view_type, None)
  File "/opt/openwisp2/env/lib/python3.5/site-packages/django/utils/functional.py", line 36, in __get__
    res = instance.__dict__[self.name] = self.func(instance)
  File "/opt/openwisp2/env/lib/python3.5/site-packages/django/urls/resolvers.py", line 533, in urlconf_module
    return import_module(self.urlconf_name)
  File "/opt/openwisp2/env/lib/python3.5/importlib/__init__.py", line 126, in import_module
    return _bootstrap._gcd_import(name[level:], package, level)
  File "<frozen importlib._bootstrap>", line 986, in _gcd_import
  File "<frozen importlib._bootstrap>", line 969, in _find_and_load
  File "<frozen importlib._bootstrap>", line 958, in _find_and_load_unlocked
  File "<frozen importlib._bootstrap>", line 673, in _load_unlocked
  File "<frozen importlib._bootstrap_external>", line 665, in exec_module
  File "<frozen importlib._bootstrap>", line 222, in _call_with_frames_removed
  File "./openwisp2/urls.py", line 19, in <module>
    url(r'^', include('openwisp_radius.urls', namespace='freeradius')),
  File "/opt/openwisp2/env/lib/python3.5/site-packages/django/urls/conf.py", line 34, in include
    urlconf_module = import_module(urlconf_module)
  File "/opt/openwisp2/env/lib/python3.5/importlib/__init__.py", line 126, in import_module
    return _bootstrap._gcd_import(name[level:], package, level)
  File "<frozen importlib._bootstrap>", line 986, in _gcd_import
  File "<frozen importlib._bootstrap>", line 969, in _find_and_load
  File "<frozen importlib._bootstrap>", line 958, in _find_and_load_unlocked
  File "<frozen importlib._bootstrap>", line 673, in _load_unlocked
  File "<frozen importlib._bootstrap_external>", line 665, in exec_module
  File "<frozen importlib._bootstrap>", line 222, in _call_with_frames_removed
  File "/opt/openwisp2/env/lib/python3.5/site-packages/openwisp_radius/urls.py", line 4, in <module>
    from .api import urls as api
  File "/opt/openwisp2/env/lib/python3.5/site-packages/openwisp_radius/api/urls.py", line 3, in <module>
    from . import views
  File "/opt/openwisp2/env/lib/python3.5/site-packages/openwisp_radius/api/views.py", line 10, in <module>
    from django_freeradius.api.views import AccountingView as BaseAccountingView
  File "/opt/openwisp2/env/lib/python3.5/site-packages/django_freeradius/api/views.py", line 15, in <module>
    from .serializers import RadiusAccountingSerializer, RadiusBatchSerializer, RadiusPostAuthSerializer
  File "/opt/openwisp2/env/lib/python3.5/site-packages/django_freeradius/api/serializers.py", line 7, in <module>
    RadiusPostAuth = swapper.load_model('django_freeradius', 'RadiusPostAuth')
  File "/opt/openwisp2/env/lib/python3.5/site-packages/swapper/__init__.py", line 94, in load_model
    "Could not find {name}!".format(name=join(app_label, model))
django.core.exceptions.ImproperlyConfigured: Could not find django_freeradius.RadiusPostAuth!

During handling of the above exception, another exception occurred:

Traceback (most recent call last):
  File "/opt/openwisp2/env/lib/python3.5/site-packages/django/core/handlers/exception.py", line 35, in inner
    response = get_response(request)
  File "/opt/openwisp2/env/lib/python3.5/site-packages/django/utils/deprecation.py", line 95, in __call__
    response = self.get_response(request)
  File "/opt/openwisp2/env/lib/python3.5/site-packages/django/core/handlers/exception.py", line 37, in inner
    response = response_for_exception(request, exc)
  File "/opt/openwisp2/env/lib/python3.5/site-packages/django/core/handlers/exception.py", line 87, in response_for_exception
    response = handle_uncaught_exception(request, get_resolver(get_urlconf()), sys.exc_info())
  File "/opt/openwisp2/env/lib/python3.5/site-packages/django/core/handlers/exception.py", line 125, in handle_uncaught_exception
    callback, param_dict = resolver.resolve_error_handler(500)
  File "/opt/openwisp2/env/lib/python3.5/site-packages/django/urls/resolvers.py", line 553, in resolve_error_handler
    callback = getattr(self.urlconf_module, 'handler%s' % view_type, None)
  File "/opt/openwisp2/env/lib/python3.5/site-packages/django/utils/functional.py", line 36, in __get__
    res = instance.__dict__[self.name] = self.func(instance)
  File "/opt/openwisp2/env/lib/python3.5/site-packages/django/urls/resolvers.py", line 533, in urlconf_module
    return import_module(self.urlconf_name)
  File "/opt/openwisp2/env/lib/python3.5/importlib/__init__.py", line 126, in import_module
    return _bootstrap._gcd_import(name[level:], package, level)
  File "<frozen importlib._bootstrap>", line 986, in _gcd_import
  File "<frozen importlib._bootstrap>", line 969, in _find_and_load
  File "<frozen importlib._bootstrap>", line 958, in _find_and_load_unlocked
  File "<frozen importlib._bootstrap>", line 673, in _load_unlocked
  File "<frozen importlib._bootstrap_external>", line 665, in exec_module
  File "<frozen importlib._bootstrap>", line 222, in _call_with_frames_removed
  File "./openwisp2/urls.py", line 19, in <module>
    url(r'^', include('openwisp_radius.urls', namespace='freeradius')),
  File "/opt/openwisp2/env/lib/python3.5/site-packages/django/urls/conf.py", line 34, in include
    urlconf_module = import_module(urlconf_module)
  File "/opt/openwisp2/env/lib/python3.5/importlib/__init__.py", line 126, in import_module
    return _bootstrap._gcd_import(name[level:], package, level)
  File "<frozen importlib._bootstrap>", line 986, in _gcd_import
  File "<frozen importlib._bootstrap>", line 969, in _find_and_load
  File "<frozen importlib._bootstrap>", line 958, in _find_and_load_unlocked
  File "<frozen importlib._bootstrap>", line 673, in _load_unlocked
  File "<frozen importlib._bootstrap_external>", line 665, in exec_module
  File "<frozen importlib._bootstrap>", line 222, in _call_with_frames_removed
  File "/opt/openwisp2/env/lib/python3.5/site-packages/openwisp_radius/urls.py", line 4, in <module>
    from .api import urls as api
  File "/opt/openwisp2/env/lib/python3.5/site-packages/openwisp_radius/api/urls.py", line 3, in <module>
    from . import views
  File "/opt/openwisp2/env/lib/python3.5/site-packages/openwisp_radius/api/views.py", line 10, in <module>
    from django_freeradius.api.views import AccountingView as BaseAccountingView
  File "/opt/openwisp2/env/lib/python3.5/site-packages/django_freeradius/api/views.py", line 15, in <module>
    from .serializers import RadiusAccountingSerializer, RadiusBatchSerializer, RadiusPostAuthSerializer
  File "/opt/openwisp2/env/lib/python3.5/site-packages/django_freeradius/api/serializers.py", line 7, in <module>
    RadiusPostAuth = swapper.load_model('django_freeradius', 'RadiusPostAuth')
  File "/opt/openwisp2/env/lib/python3.5/site-packages/swapper/__init__.py", line 94, in load_model
    "Could not find {name}!".format(name=join(app_label, model))
django.core.exceptions.ImproperlyConfigured: Could not find django_freeradius.RadiusPostAuth!

During handling of the above exception, another exception occurred:

Traceback (most recent call last):
  File "/opt/openwisp2/env/lib/python3.5/site-packages/django/core/handlers/exception.py", line 35, in inner
    response = get_response(request)
  File "/opt/openwisp2/env/lib/python3.5/site-packages/django/utils/deprecation.py", line 95, in __call__
    response = self.get_response(request)
  File "/opt/openwisp2/env/lib/python3.5/site-packages/django/core/handlers/exception.py", line 37, in inner
    response = response_for_exception(request, exc)
  File "/opt/openwisp2/env/lib/python3.5/site-packages/django/core/handlers/exception.py", line 87, in response_for_exception
    response = handle_uncaught_exception(request, get_resolver(get_urlconf()), sys.exc_info())
  File "/opt/openwisp2/env/lib/python3.5/site-packages/django/core/handlers/exception.py", line 125, in handle_uncaught_exception
    callback, param_dict = resolver.resolve_error_handler(500)
  File "/opt/openwisp2/env/lib/python3.5/site-packages/django/urls/resolvers.py", line 553, in resolve_error_handler
    callback = getattr(self.urlconf_module, 'handler%s' % view_type, None)
  File "/opt/openwisp2/env/lib/python3.5/site-packages/django/utils/functional.py", line 36, in __get__
    res = instance.__dict__[self.name] = self.func(instance)
  File "/opt/openwisp2/env/lib/python3.5/site-packages/django/urls/resolvers.py", line 533, in urlconf_module
    return import_module(self.urlconf_name)
  File "/opt/openwisp2/env/lib/python3.5/importlib/__init__.py", line 126, in import_module
    return _bootstrap._gcd_import(name[level:], package, level)
  File "<frozen importlib._bootstrap>", line 986, in _gcd_import
  File "<frozen importlib._bootstrap>", line 969, in _find_and_load
  File "<frozen importlib._bootstrap>", line 958, in _find_and_load_unlocked
  File "<frozen importlib._bootstrap>", line 673, in _load_unlocked
  File "<frozen importlib._bootstrap_external>", line 665, in exec_module
  File "<frozen importlib._bootstrap>", line 222, in _call_with_frames_removed
  File "./openwisp2/urls.py", line 19, in <module>
    url(r'^', include('openwisp_radius.urls', namespace='freeradius')),
  File "/opt/openwisp2/env/lib/python3.5/site-packages/django/urls/conf.py", line 34, in include
    urlconf_module = import_module(urlconf_module)
  File "/opt/openwisp2/env/lib/python3.5/importlib/__init__.py", line 126, in import_module
    return _bootstrap._gcd_import(name[level:], package, level)
  File "<frozen importlib._bootstrap>", line 986, in _gcd_import
  File "<frozen importlib._bootstrap>", line 969, in _find_and_load
  File "<frozen importlib._bootstrap>", line 958, in _find_and_load_unlocked
  File "<frozen importlib._bootstrap>", line 673, in _load_unlocked
  File "<frozen importlib._bootstrap_external>", line 665, in exec_module
  File "<frozen importlib._bootstrap>", line 222, in _call_with_frames_removed
  File "/opt/openwisp2/env/lib/python3.5/site-packages/openwisp_radius/urls.py", line 4, in <module>
    from .api import urls as api
  File "/opt/openwisp2/env/lib/python3.5/site-packages/openwisp_radius/api/urls.py", line 3, in <module>
    from . import views
  File "/opt/openwisp2/env/lib/python3.5/site-packages/openwisp_radius/api/views.py", line 10, in <module>
    from django_freeradius.api.views import AccountingView as BaseAccountingView
  File "/opt/openwisp2/env/lib/python3.5/site-packages/django_freeradius/api/views.py", line 15, in <module>
    from .serializers import RadiusAccountingSerializer, RadiusBatchSerializer, RadiusPostAuthSerializer
  File "/opt/openwisp2/env/lib/python3.5/site-packages/django_freeradius/api/serializers.py", line 7, in <module>
    RadiusPostAuth = swapper.load_model('django_freeradius', 'RadiusPostAuth')
  File "/opt/openwisp2/env/lib/python3.5/site-packages/swapper/__init__.py", line 94, in load_model
    "Could not find {name}!".format(name=join(app_label, model))
django.core.exceptions.ImproperlyConfigured: Could not find django_freeradius.RadiusPostAuth!


[ERROR 2019-08-12 14:04:57,738] module: exception, process: 15327, thread: 140303547352832
Internal Server Error: /admin/
Traceback (most recent call last):
  File "/opt/openwisp2/env/lib/python3.5/site-packages/django/core/handlers/exception.py", line 35, in inner
    response = get_response(request)
  File "/opt/openwisp2/env/lib/python3.5/site-packages/django/core/handlers/base.py", line 113, in _get_response
    resolver_match = resolver.resolve(request.path_info)
  File "/opt/openwisp2/env/lib/python3.5/site-packages/django/urls/resolvers.py", line 498, in resolve
    for pattern in self.url_patterns:
  File "/opt/openwisp2/env/lib/python3.5/site-packages/django/utils/functional.py", line 36, in __get__
    res = instance.__dict__[self.name] = self.func(instance)
  File "/opt/openwisp2/env/lib/python3.5/site-packages/django/urls/resolvers.py", line 540, in url_patterns
    patterns = getattr(self.urlconf_module, "urlpatterns", self.urlconf_module)
  File "/opt/openwisp2/env/lib/python3.5/site-packages/django/utils/functional.py", line 36, in __get__
    res = instance.__dict__[self.name] = self.func(instance)
  File "/opt/openwisp2/env/lib/python3.5/site-packages/django/urls/resolvers.py", line 533, in urlconf_module
    return import_module(self.urlconf_name)
  File "/opt/openwisp2/env/lib/python3.5/importlib/__init__.py", line 126, in import_module
    return _bootstrap._gcd_import(name[level:], package, level)
  File "<frozen importlib._bootstrap>", line 986, in _gcd_import
  File "<frozen importlib._bootstrap>", line 969, in _find_and_load
  File "<frozen importlib._bootstrap>", line 958, in _find_and_load_unlocked
  File "<frozen importlib._bootstrap>", line 673, in _load_unlocked
  File "<frozen importlib._bootstrap_external>", line 665, in exec_module
  File "<frozen importlib._bootstrap>", line 222, in _call_with_frames_removed
  File "./openwisp2/urls.py", line 19, in <module>
    url(r'^', include('openwisp_radius.urls', namespace='freeradius')),
  File "/opt/openwisp2/env/lib/python3.5/site-packages/django/urls/conf.py", line 34, in include
    urlconf_module = import_module(urlconf_module)
  File "/opt/openwisp2/env/lib/python3.5/importlib/__init__.py", line 126, in import_module
    return _bootstrap._gcd_import(name[level:], package, level)
  File "<frozen importlib._bootstrap>", line 986, in _gcd_import
  File "<frozen importlib._bootstrap>", line 969, in _find_and_load
  File "<frozen importlib._bootstrap>", line 958, in _find_and_load_unlocked
  File "<frozen importlib._bootstrap>", line 673, in _load_unlocked
  File "<frozen importlib._bootstrap_external>", line 665, in exec_module
  File "<frozen importlib._bootstrap>", line 222, in _call_with_frames_removed
  File "/opt/openwisp2/env/lib/python3.5/site-packages/openwisp_radius/urls.py", line 4, in <module>
    from .api import urls as api
  File "/opt/openwisp2/env/lib/python3.5/site-packages/openwisp_radius/api/urls.py", line 3, in <module>
    from . import views
  File "/opt/openwisp2/env/lib/python3.5/site-packages/openwisp_radius/api/views.py", line 10, in <module>
    from django_freeradius.api.views import AccountingView as BaseAccountingView
  File "/opt/openwisp2/env/lib/python3.5/site-packages/django_freeradius/api/views.py", line 15, in <module>
    from .serializers import RadiusAccountingSerializer, RadiusBatchSerializer, RadiusPostAuthSerializer
  File "/opt/openwisp2/env/lib/python3.5/site-packages/django_freeradius/api/serializers.py", line 7, in <module>
    RadiusPostAuth = swapper.load_model('django_freeradius', 'RadiusPostAuth')
  File "/opt/openwisp2/env/lib/python3.5/site-packages/swapper/__init__.py", line 94, in load_model
    "Could not find {name}!".format(name=join(app_label, model))
django.core.exceptions.ImproperlyConfigured: Could not find django_freeradius.RadiusPostAuth!

During handling of the above exception, another exception occurred:

Traceback (most recent call last):
  File "/opt/openwisp2/env/lib/python3.5/site-packages/django/core/handlers/exception.py", line 35, in inner
    response = get_response(request)
  File "/opt/openwisp2/env/lib/python3.5/site-packages/django/utils/deprecation.py", line 95, in __call__
    response = self.get_response(request)
  File "/opt/openwisp2/env/lib/python3.5/site-packages/django/core/handlers/exception.py", line 37, in inner
    response = response_for_exception(request, exc)
  File "/opt/openwisp2/env/lib/python3.5/site-packages/django/core/handlers/exception.py", line 87, in response_for_exception
    response = handle_uncaught_exception(request, get_resolver(get_urlconf()), sys.exc_info())
  File "/opt/openwisp2/env/lib/python3.5/site-packages/django/core/handlers/exception.py", line 125, in handle_uncaught_exception
    callback, param_dict = resolver.resolve_error_handler(500)
  File "/opt/openwisp2/env/lib/python3.5/site-packages/django/urls/resolvers.py", line 553, in resolve_error_handler
    callback = getattr(self.urlconf_module, 'handler%s' % view_type, None)
  File "/opt/openwisp2/env/lib/python3.5/site-packages/django/utils/functional.py", line 36, in __get__
    res = instance.__dict__[self.name] = self.func(instance)
  File "/opt/openwisp2/env/lib/python3.5/site-packages/django/urls/resolvers.py", line 533, in urlconf_module
    return import_module(self.urlconf_name)
  File "/opt/openwisp2/env/lib/python3.5/importlib/__init__.py", line 126, in import_module
    return _bootstrap._gcd_import(name[level:], package, level)
  File "<frozen importlib._bootstrap>", line 986, in _gcd_import
  File "<frozen importlib._bootstrap>", line 969, in _find_and_load
  File "<frozen importlib._bootstrap>", line 958, in _find_and_load_unlocked
  File "<frozen importlib._bootstrap>", line 673, in _load_unlocked
  File "<frozen importlib._bootstrap_external>", line 665, in exec_module
  File "<frozen importlib._bootstrap>", line 222, in _call_with_frames_removed
  File "./openwisp2/urls.py", line 19, in <module>
    url(r'^', include('openwisp_radius.urls', namespace='freeradius')),
  File "/opt/openwisp2/env/lib/python3.5/site-packages/django/urls/conf.py", line 34, in include
    urlconf_module = import_module(urlconf_module)
  File "/opt/openwisp2/env/lib/python3.5/importlib/__init__.py", line 126, in import_module
    return _bootstrap._gcd_import(name[level:], package, level)
  File "<frozen importlib._bootstrap>", line 986, in _gcd_import
  File "<frozen importlib._bootstrap>", line 969, in _find_and_load
  File "<frozen importlib._bootstrap>", line 958, in _find_and_load_unlocked
  File "<frozen importlib._bootstrap>", line 673, in _load_unlocked
  File "<frozen importlib._bootstrap_external>", line 665, in exec_module
  File "<frozen importlib._bootstrap>", line 222, in _call_with_frames_removed
  File "/opt/openwisp2/env/lib/python3.5/site-packages/openwisp_radius/urls.py", line 4, in <module>
    from .api import urls as api
  File "/opt/openwisp2/env/lib/python3.5/site-packages/openwisp_radius/api/urls.py", line 3, in <module>
    from . import views
  File "/opt/openwisp2/env/lib/python3.5/site-packages/openwisp_radius/api/views.py", line 10, in <module>
    from django_freeradius.api.views import AccountingView as BaseAccountingView
  File "/opt/openwisp2/env/lib/python3.5/site-packages/django_freeradius/api/views.py", line 15, in <module>
    from .serializers import RadiusAccountingSerializer, RadiusBatchSerializer, RadiusPostAuthSerializer
  File "/opt/openwisp2/env/lib/python3.5/site-packages/django_freeradius/api/serializers.py", line 7, in <module>
    RadiusPostAuth = swapper.load_model('django_freeradius', 'RadiusPostAuth')
  File "/opt/openwisp2/env/lib/python3.5/site-packages/swapper/__init__.py", line 94, in load_model
    "Could not find {name}!".format(name=join(app_label, model))
django.core.exceptions.ImproperlyConfigured: Could not find django_freeradius.RadiusPostAuth!

During handling of the above exception, another exception occurred:

Traceback (most recent call last):
  File "/opt/openwisp2/env/lib/python3.5/site-packages/django/core/handlers/exception.py", line 35, in inner
    response = get_response(request)
  File "/opt/openwisp2/env/lib/python3.5/site-packages/django/utils/deprecation.py", line 95, in __call__
    response = self.get_response(request)
  File "/opt/openwisp2/env/lib/python3.5/site-packages/django/core/handlers/exception.py", line 37, in inner
    response = response_for_exception(request, exc)
  File "/opt/openwisp2/env/lib/python3.5/site-packages/django/core/handlers/exception.py", line 87, in response_for_exception
    response = handle_uncaught_exception(request, get_resolver(get_urlconf()), sys.exc_info())
  File "/opt/openwisp2/env/lib/python3.5/site-packages/django/core/handlers/exception.py", line 125, in handle_uncaught_exception
    callback, param_dict = resolver.resolve_error_handler(500)
  File "/opt/openwisp2/env/lib/python3.5/site-packages/django/urls/resolvers.py", line 553, in resolve_error_handler
    callback = getattr(self.urlconf_module, 'handler%s' % view_type, None)
  File "/opt/openwisp2/env/lib/python3.5/site-packages/django/utils/functional.py", line 36, in __get__
    res = instance.__dict__[self.name] = self.func(instance)
  File "/opt/openwisp2/env/lib/python3.5/site-packages/django/urls/resolvers.py", line 533, in urlconf_module
    return import_module(self.urlconf_name)
  File "/opt/openwisp2/env/lib/python3.5/importlib/__init__.py", line 126, in import_module
    return _bootstrap._gcd_import(name[level:], package, level)
  File "<frozen importlib._bootstrap>", line 986, in _gcd_import
  File "<frozen importlib._bootstrap>", line 969, in _find_and_load
  File "<frozen importlib._bootstrap>", line 958, in _find_and_load_unlocked
  File "<frozen importlib._bootstrap>", line 673, in _load_unlocked
  File "<frozen importlib._bootstrap_external>", line 665, in exec_module
  File "<frozen importlib._bootstrap>", line 222, in _call_with_frames_removed
  File "./openwisp2/urls.py", line 19, in <module>
    url(r'^', include('openwisp_radius.urls', namespace='freeradius')),
  File "/opt/openwisp2/env/lib/python3.5/site-packages/django/urls/conf.py", line 34, in include
    urlconf_module = import_module(urlconf_module)
  File "/opt/openwisp2/env/lib/python3.5/importlib/__init__.py", line 126, in import_module
    return _bootstrap._gcd_import(name[level:], package, level)
  File "<frozen importlib._bootstrap>", line 986, in _gcd_import
  File "<frozen importlib._bootstrap>", line 969, in _find_and_load
  File "<frozen importlib._bootstrap>", line 958, in _find_and_load_unlocked
  File "<frozen importlib._bootstrap>", line 673, in _load_unlocked
  File "<frozen importlib._bootstrap_external>", line 665, in exec_module
  File "<frozen importlib._bootstrap>", line 222, in _call_with_frames_removed
  File "/opt/openwisp2/env/lib/python3.5/site-packages/openwisp_radius/urls.py", line 4, in <module>
    from .api import urls as api
  File "/opt/openwisp2/env/lib/python3.5/site-packages/openwisp_radius/api/urls.py", line 3, in <module>
    from . import views
  File "/opt/openwisp2/env/lib/python3.5/site-packages/openwisp_radius/api/views.py", line 10, in <module>
    from django_freeradius.api.views import AccountingView as BaseAccountingView
  File "/opt/openwisp2/env/lib/python3.5/site-packages/django_freeradius/api/views.py", line 15, in <module>
    from .serializers import RadiusAccountingSerializer, RadiusBatchSerializer, RadiusPostAuthSerializer
  File "/opt/openwisp2/env/lib/python3.5/site-packages/django_freeradius/api/serializers.py", line 7, in <module>
    RadiusPostAuth = swapper.load_model('django_freeradius', 'RadiusPostAuth')
  File "/opt/openwisp2/env/lib/python3.5/site-packages/swapper/__init__.py", line 94, in load_model
    "Could not find {name}!".format(name=join(app_label, model))
django.core.exceptions.ImproperlyConfigured: Could not find django_freeradius.RadiusPostAuth!

During handling of the above exception, another exception occurred:

Traceback (most recent call last):
  File "/opt/openwisp2/env/lib/python3.5/site-packages/django/core/handlers/exception.py", line 35, in inner
    response = get_response(request)
  File "/opt/openwisp2/env/lib/python3.5/site-packages/django/utils/deprecation.py", line 95, in __call__
    response = self.get_response(request)
  File "/opt/openwisp2/env/lib/python3.5/site-packages/django/core/handlers/exception.py", line 37, in inner
    response = response_for_exception(request, exc)
  File "/opt/openwisp2/env/lib/python3.5/site-packages/django/core/handlers/exception.py", line 87, in response_for_exception
    response = handle_uncaught_exception(request, get_resolver(get_urlconf()), sys.exc_info())
  File "/opt/openwisp2/env/lib/python3.5/site-packages/django/core/handlers/exception.py", line 125, in handle_uncaught_exception
    callback, param_dict = resolver.resolve_error_handler(500)
  File "/opt/openwisp2/env/lib/python3.5/site-packages/django/urls/resolvers.py", line 553, in resolve_error_handler
    callback = getattr(self.urlconf_module, 'handler%s' % view_type, None)
  File "/opt/openwisp2/env/lib/python3.5/site-packages/django/utils/functional.py", line 36, in __get__
    res = instance.__dict__[self.name] = self.func(instance)
  File "/opt/openwisp2/env/lib/python3.5/site-packages/django/urls/resolvers.py", line 533, in urlconf_module
    return import_module(self.urlconf_name)
  File "/opt/openwisp2/env/lib/python3.5/importlib/__init__.py", line 126, in import_module
    return _bootstrap._gcd_import(name[level:], package, level)
  File "<frozen importlib._bootstrap>", line 986, in _gcd_import
  File "<frozen importlib._bootstrap>", line 969, in _find_and_load
  File "<frozen importlib._bootstrap>", line 958, in _find_and_load_unlocked
  File "<frozen importlib._bootstrap>", line 673, in _load_unlocked
  File "<frozen importlib._bootstrap_external>", line 665, in exec_module
  File "<frozen importlib._bootstrap>", line 222, in _call_with_frames_removed
  File "./openwisp2/urls.py", line 19, in <module>
    url(r'^', include('openwisp_radius.urls', namespace='freeradius')),
  File "/opt/openwisp2/env/lib/python3.5/site-packages/django/urls/conf.py", line 34, in include
    urlconf_module = import_module(urlconf_module)
  File "/opt/openwisp2/env/lib/python3.5/importlib/__init__.py", line 126, in import_module
    return _bootstrap._gcd_import(name[level:], package, level)
  File "<frozen importlib._bootstrap>", line 986, in _gcd_import
  File "<frozen importlib._bootstrap>", line 969, in _find_and_load
  File "<frozen importlib._bootstrap>", line 958, in _find_and_load_unlocked
  File "<frozen importlib._bootstrap>", line 673, in _load_unlocked
  File "<frozen importlib._bootstrap_external>", line 665, in exec_module
  File "<frozen importlib._bootstrap>", line 222, in _call_with_frames_removed
  File "/opt/openwisp2/env/lib/python3.5/site-packages/openwisp_radius/urls.py", line 4, in <module>
    from .api import urls as api
  File "/opt/openwisp2/env/lib/python3.5/site-packages/openwisp_radius/api/urls.py", line 3, in <module>
    from . import views
  File "/opt/openwisp2/env/lib/python3.5/site-packages/openwisp_radius/api/views.py", line 10, in <module>
    from django_freeradius.api.views import AccountingView as BaseAccountingView
  File "/opt/openwisp2/env/lib/python3.5/site-packages/django_freeradius/api/views.py", line 15, in <module>
    from .serializers import RadiusAccountingSerializer, RadiusBatchSerializer, RadiusPostAuthSerializer
  File "/opt/openwisp2/env/lib/python3.5/site-packages/django_freeradius/api/serializers.py", line 7, in <module>
    RadiusPostAuth = swapper.load_model('django_freeradius', 'RadiusPostAuth')
  File "/opt/openwisp2/env/lib/python3.5/site-packages/swapper/__init__.py", line 94, in load_model
    "Could not find {name}!".format(name=join(app_label, model))
django.core.exceptions.ImproperlyConfigured: Could not find django_freeradius.RadiusPostAuth!

During handling of the above exception, another exception occurred:

Traceback (most recent call last):
  File "/opt/openwisp2/env/lib/python3.5/site-packages/django/core/handlers/exception.py", line 35, in inner
    response = get_response(request)
  File "/opt/openwisp2/env/lib/python3.5/site-packages/django/utils/deprecation.py", line 95, in __call__
    response = self.get_response(request)
  File "/opt/openwisp2/env/lib/python3.5/site-packages/django/core/handlers/exception.py", line 37, in inner
    response = response_for_exception(request, exc)
  File "/opt/openwisp2/env/lib/python3.5/site-packages/django/core/handlers/exception.py", line 87, in response_for_exception
    response = handle_uncaught_exception(request, get_resolver(get_urlconf()), sys.exc_info())
  File "/opt/openwisp2/env/lib/python3.5/site-packages/django/core/handlers/exception.py", line 125, in handle_uncaught_exception
    callback, param_dict = resolver.resolve_error_handler(500)
  File "/opt/openwisp2/env/lib/python3.5/site-packages/django/urls/resolvers.py", line 553, in resolve_error_handler
    callback = getattr(self.urlconf_module, 'handler%s' % view_type, None)
  File "/opt/openwisp2/env/lib/python3.5/site-packages/django/utils/functional.py", line 36, in __get__
    res = instance.__dict__[self.name] = self.func(instance)
  File "/opt/openwisp2/env/lib/python3.5/site-packages/django/urls/resolvers.py", line 533, in urlconf_module
    return import_module(self.urlconf_name)
  File "/opt/openwisp2/env/lib/python3.5/importlib/__init__.py", line 126, in import_module
    return _bootstrap._gcd_import(name[level:], package, level)
  File "<frozen importlib._bootstrap>", line 986, in _gcd_import
  File "<frozen importlib._bootstrap>", line 969, in _find_and_load
  File "<frozen importlib._bootstrap>", line 958, in _find_and_load_unlocked
  File "<frozen importlib._bootstrap>", line 673, in _load_unlocked
  File "<frozen importlib._bootstrap_external>", line 665, in exec_module
  File "<frozen importlib._bootstrap>", line 222, in _call_with_frames_removed
  File "./openwisp2/urls.py", line 19, in <module>
    url(r'^', include('openwisp_radius.urls', namespace='freeradius')),
  File "/opt/openwisp2/env/lib/python3.5/site-packages/django/urls/conf.py", line 34, in include
    urlconf_module = import_module(urlconf_module)
  File "/opt/openwisp2/env/lib/python3.5/importlib/__init__.py", line 126, in import_module
    return _bootstrap._gcd_import(name[level:], package, level)
  File "<frozen importlib._bootstrap>", line 986, in _gcd_import
  File "<frozen importlib._bootstrap>", line 969, in _find_and_load
  File "<frozen importlib._bootstrap>", line 958, in _find_and_load_unlocked
  File "<frozen importlib._bootstrap>", line 673, in _load_unlocked
  File "<frozen importlib._bootstrap_external>", line 665, in exec_module
  File "<frozen importlib._bootstrap>", line 222, in _call_with_frames_removed
  File "/opt/openwisp2/env/lib/python3.5/site-packages/openwisp_radius/urls.py", line 4, in <module>
    from .api import urls as api
  File "/opt/openwisp2/env/lib/python3.5/site-packages/openwisp_radius/api/urls.py", line 3, in <module>
    from . import views
  File "/opt/openwisp2/env/lib/python3.5/site-packages/openwisp_radius/api/views.py", line 10, in <module>
    from django_freeradius.api.views import AccountingView as BaseAccountingView
  File "/opt/openwisp2/env/lib/python3.5/site-packages/django_freeradius/api/views.py", line 15, in <module>
    from .serializers import RadiusAccountingSerializer, RadiusBatchSerializer, RadiusPostAuthSerializer
  File "/opt/openwisp2/env/lib/python3.5/site-packages/django_freeradius/api/serializers.py", line 7, in <module>
    RadiusPostAuth = swapper.load_model('django_freeradius', 'RadiusPostAuth')
  File "/opt/openwisp2/env/lib/python3.5/site-packages/swapper/__init__.py", line 94, in load_model
    "Could not find {name}!".format(name=join(app_label, model))
django.core.exceptions.ImproperlyConfigured: Could not find django_freeradius.RadiusPostAuth!


[ERROR 2019-08-12 14:04:58,248] module: exception, process: 15327, thread: 140303547352832
Internal Server Error: /admin/
Traceback (most recent call last):
  File "/opt/openwisp2/env/lib/python3.5/site-packages/django/core/handlers/exception.py", line 35, in inner
    response = get_response(request)
  File "/opt/openwisp2/env/lib/python3.5/site-packages/django/core/handlers/base.py", line 113, in _get_response
    resolver_match = resolver.resolve(request.path_info)
  File "/opt/openwisp2/env/lib/python3.5/site-packages/django/urls/resolvers.py", line 498, in resolve
    for pattern in self.url_patterns:
  File "/opt/openwisp2/env/lib/python3.5/site-packages/django/utils/functional.py", line 36, in __get__
    res = instance.__dict__[self.name] = self.func(instance)
  File "/opt/openwisp2/env/lib/python3.5/site-packages/django/urls/resolvers.py", line 540, in url_patterns
    patterns = getattr(self.urlconf_module, "urlpatterns", self.urlconf_module)
  File "/opt/openwisp2/env/lib/python3.5/site-packages/django/utils/functional.py", line 36, in __get__
    res = instance.__dict__[self.name] = self.func(instance)
  File "/opt/openwisp2/env/lib/python3.5/site-packages/django/urls/resolvers.py", line 533, in urlconf_module
    return import_module(self.urlconf_name)
  File "/opt/openwisp2/env/lib/python3.5/importlib/__init__.py", line 126, in import_module
    return _bootstrap._gcd_import(name[level:], package, level)
  File "<frozen importlib._bootstrap>", line 986, in _gcd_import
  File "<frozen importlib._bootstrap>", line 969, in _find_and_load
  File "<frozen importlib._bootstrap>", line 958, in _find_and_load_unlocked
  File "<frozen importlib._bootstrap>", line 673, in _load_unlocked
  File "<frozen importlib._bootstrap_external>", line 665, in exec_module
  File "<frozen importlib._bootstrap>", line 222, in _call_with_frames_removed
  File "./openwisp2/urls.py", line 19, in <module>
    url(r'^', include('openwisp_radius.urls', namespace='freeradius')),
  File "/opt/openwisp2/env/lib/python3.5/site-packages/django/urls/conf.py", line 34, in include
    urlconf_module = import_module(urlconf_module)
  File "/opt/openwisp2/env/lib/python3.5/importlib/__init__.py", line 126, in import_module
    return _bootstrap._gcd_import(name[level:], package, level)
  File "<frozen importlib._bootstrap>", line 986, in _gcd_import
  File "<frozen importlib._bootstrap>", line 969, in _find_and_load
  File "<frozen importlib._bootstrap>", line 958, in _find_and_load_unlocked
  File "<frozen importlib._bootstrap>", line 673, in _load_unlocked
  File "<frozen importlib._bootstrap_external>", line 665, in exec_module
  File "<frozen importlib._bootstrap>", line 222, in _call_with_frames_removed
  File "/opt/openwisp2/env/lib/python3.5/site-packages/openwisp_radius/urls.py", line 4, in <module>
    from .api import urls as api
  File "/opt/openwisp2/env/lib/python3.5/site-packages/openwisp_radius/api/urls.py", line 3, in <module>
    from . import views
  File "/opt/openwisp2/env/lib/python3.5/site-packages/openwisp_radius/api/views.py", line 10, in <module>
    from django_freeradius.api.views import AccountingView as BaseAccountingView
  File "/opt/openwisp2/env/lib/python3.5/site-packages/django_freeradius/api/views.py", line 15, in <module>
    from .serializers import RadiusAccountingSerializer, RadiusBatchSerializer, RadiusPostAuthSerializer
  File "/opt/openwisp2/env/lib/python3.5/site-packages/django_freeradius/api/serializers.py", line 7, in <module>
    RadiusPostAuth = swapper.load_model('django_freeradius', 'RadiusPostAuth')
  File "/opt/openwisp2/env/lib/python3.5/site-packages/swapper/__init__.py", line 94, in load_model
    "Could not find {name}!".format(name=join(app_label, model))
django.core.exceptions.ImproperlyConfigured: Could not find django_freeradius.RadiusPostAuth!

During handling of the above exception, another exception occurred:

Traceback (most recent call last):
  File "/opt/openwisp2/env/lib/python3.5/site-packages/django/core/handlers/exception.py", line 35, in inner
    response = get_response(request)
  File "/opt/openwisp2/env/lib/python3.5/site-packages/django/utils/deprecation.py", line 95, in __call__
    response = self.get_response(request)
  File "/opt/openwisp2/env/lib/python3.5/site-packages/django/core/handlers/exception.py", line 37, in inner
    response = response_for_exception(request, exc)
  File "/opt/openwisp2/env/lib/python3.5/site-packages/django/core/handlers/exception.py", line 87, in response_for_exception
    response = handle_uncaught_exception(request, get_resolver(get_urlconf()), sys.exc_info())
  File "/opt/openwisp2/env/lib/python3.5/site-packages/django/core/handlers/exception.py", line 125, in handle_uncaught_exception
    callback, param_dict = resolver.resolve_error_handler(500)
  File "/opt/openwisp2/env/lib/python3.5/site-packages/django/urls/resolvers.py", line 553, in resolve_error_handler
    callback = getattr(self.urlconf_module, 'handler%s' % view_type, None)
  File "/opt/openwisp2/env/lib/python3.5/site-packages/django/utils/functional.py", line 36, in __get__
    res = instance.__dict__[self.name] = self.func(instance)
  File "/opt/openwisp2/env/lib/python3.5/site-packages/django/urls/resolvers.py", line 533, in urlconf_module
    return import_module(self.urlconf_name)
  File "/opt/openwisp2/env/lib/python3.5/importlib/__init__.py", line 126, in import_module
    return _bootstrap._gcd_import(name[level:], package, level)
  File "<frozen importlib._bootstrap>", line 986, in _gcd_import
  File "<frozen importlib._bootstrap>", line 969, in _find_and_load
  File "<frozen importlib._bootstrap>", line 958, in _find_and_load_unlocked
  File "<frozen importlib._bootstrap>", line 673, in _load_unlocked
  File "<frozen importlib._bootstrap_external>", line 665, in exec_module
  File "<frozen importlib._bootstrap>", line 222, in _call_with_frames_removed
  File "./openwisp2/urls.py", line 19, in <module>
    url(r'^', include('openwisp_radius.urls', namespace='freeradius')),
  File "/opt/openwisp2/env/lib/python3.5/site-packages/django/urls/conf.py", line 34, in include
    urlconf_module = import_module(urlconf_module)
  File "/opt/openwisp2/env/lib/python3.5/importlib/__init__.py", line 126, in import_module
    return _bootstrap._gcd_import(name[level:], package, level)
  File "<frozen importlib._bootstrap>", line 986, in _gcd_import
  File "<frozen importlib._bootstrap>", line 969, in _find_and_load
  File "<frozen importlib._bootstrap>", line 958, in _find_and_load_unlocked
  File "<frozen importlib._bootstrap>", line 673, in _load_unlocked
  File "<frozen importlib._bootstrap_external>", line 665, in exec_module
  File "<frozen importlib._bootstrap>", line 222, in _call_with_frames_removed
  File "/opt/openwisp2/env/lib/python3.5/site-packages/openwisp_radius/urls.py", line 4, in <module>
    from .api import urls as api
  File "/opt/openwisp2/env/lib/python3.5/site-packages/openwisp_radius/api/urls.py", line 3, in <module>
    from . import views
  File "/opt/openwisp2/env/lib/python3.5/site-packages/openwisp_radius/api/views.py", line 10, in <module>
    from django_freeradius.api.views import AccountingView as BaseAccountingView
  File "/opt/openwisp2/env/lib/python3.5/site-packages/django_freeradius/api/views.py", line 15, in <module>
    from .serializers import RadiusAccountingSerializer, RadiusBatchSerializer, RadiusPostAuthSerializer
  File "/opt/openwisp2/env/lib/python3.5/site-packages/django_freeradius/api/serializers.py", line 7, in <module>
    RadiusPostAuth = swapper.load_model('django_freeradius', 'RadiusPostAuth')
  File "/opt/openwisp2/env/lib/python3.5/site-packages/swapper/__init__.py", line 94, in load_model
    "Could not find {name}!".format(name=join(app_label, model))
django.core.exceptions.ImproperlyConfigured: Could not find django_freeradius.RadiusPostAuth!

During handling of the above exception, another exception occurred:

Traceback (most recent call last):
  File "/opt/openwisp2/env/lib/python3.5/site-packages/django/core/handlers/exception.py", line 35, in inner
    response = get_response(request)
  File "/opt/openwisp2/env/lib/python3.5/site-packages/django/utils/deprecation.py", line 95, in __call__
    response = self.get_response(request)
  File "/opt/openwisp2/env/lib/python3.5/site-packages/django/core/handlers/exception.py", line 37, in inner
    response = response_for_exception(request, exc)
  File "/opt/openwisp2/env/lib/python3.5/site-packages/django/core/handlers/exception.py", line 87, in response_for_exception
    response = handle_uncaught_exception(request, get_resolver(get_urlconf()), sys.exc_info())
  File "/opt/openwisp2/env/lib/python3.5/site-packages/django/core/handlers/exception.py", line 125, in handle_uncaught_exception
    callback, param_dict = resolver.resolve_error_handler(500)
  File "/opt/openwisp2/env/lib/python3.5/site-packages/django/urls/resolvers.py", line 553, in resolve_error_handler
    callback = getattr(self.urlconf_module, 'handler%s' % view_type, None)
  File "/opt/openwisp2/env/lib/python3.5/site-packages/django/utils/functional.py", line 36, in __get__
    res = instance.__dict__[self.name] = self.func(instance)
  File "/opt/openwisp2/env/lib/python3.5/site-packages/django/urls/resolvers.py", line 533, in urlconf_module
    return import_module(self.urlconf_name)
  File "/opt/openwisp2/env/lib/python3.5/importlib/__init__.py", line 126, in import_module
    return _bootstrap._gcd_import(name[level:], package, level)
  File "<frozen importlib._bootstrap>", line 986, in _gcd_import
  File "<frozen importlib._bootstrap>", line 969, in _find_and_load
  File "<frozen importlib._bootstrap>", line 958, in _find_and_load_unlocked
  File "<frozen importlib._bootstrap>", line 673, in _load_unlocked
  File "<frozen importlib._bootstrap_external>", line 665, in exec_module
  File "<frozen importlib._bootstrap>", line 222, in _call_with_frames_removed
  File "./openwisp2/urls.py", line 19, in <module>
    url(r'^', include('openwisp_radius.urls', namespace='freeradius')),
  File "/opt/openwisp2/env/lib/python3.5/site-packages/django/urls/conf.py", line 34, in include
    urlconf_module = import_module(urlconf_module)
  File "/opt/openwisp2/env/lib/python3.5/importlib/__init__.py", line 126, in import_module
    return _bootstrap._gcd_import(name[level:], package, level)
  File "<frozen importlib._bootstrap>", line 986, in _gcd_import
  File "<frozen importlib._bootstrap>", line 969, in _find_and_load
  File "<frozen importlib._bootstrap>", line 958, in _find_and_load_unlocked
  File "<frozen importlib._bootstrap>", line 673, in _load_unlocked
  File "<frozen importlib._bootstrap_external>", line 665, in exec_module
  File "<frozen importlib._bootstrap>", line 222, in _call_with_frames_removed
  File "/opt/openwisp2/env/lib/python3.5/site-packages/openwisp_radius/urls.py", line 4, in <module>
    from .api import urls as api
  File "/opt/openwisp2/env/lib/python3.5/site-packages/openwisp_radius/api/urls.py", line 3, in <module>
    from . import views
  File "/opt/openwisp2/env/lib/python3.5/site-packages/openwisp_radius/api/views.py", line 10, in <module>
    from django_freeradius.api.views import AccountingView as BaseAccountingView
  File "/opt/openwisp2/env/lib/python3.5/site-packages/django_freeradius/api/views.py", line 15, in <module>
    from .serializers import RadiusAccountingSerializer, RadiusBatchSerializer, RadiusPostAuthSerializer
  File "/opt/openwisp2/env/lib/python3.5/site-packages/django_freeradius/api/serializers.py", line 7, in <module>
    RadiusPostAuth = swapper.load_model('django_freeradius', 'RadiusPostAuth')
  File "/opt/openwisp2/env/lib/python3.5/site-packages/swapper/__init__.py", line 94, in load_model
    "Could not find {name}!".format(name=join(app_label, model))
django.core.exceptions.ImproperlyConfigured: Could not find django_freeradius.RadiusPostAuth!

During handling of the above exception, another exception occurred:

Traceback (most recent call last):
  File "/opt/openwisp2/env/lib/python3.5/site-packages/django/core/handlers/exception.py", line 35, in inner
    response = get_response(request)
  File "/opt/openwisp2/env/lib/python3.5/site-packages/django/utils/deprecation.py", line 95, in __call__
    response = self.get_response(request)
  File "/opt/openwisp2/env/lib/python3.5/site-packages/django/core/handlers/exception.py", line 37, in inner
    response = response_for_exception(request, exc)
  File "/opt/openwisp2/env/lib/python3.5/site-packages/django/core/handlers/exception.py", line 87, in response_for_exception
    response = handle_uncaught_exception(request, get_resolver(get_urlconf()), sys.exc_info())
  File "/opt/openwisp2/env/lib/python3.5/site-packages/django/core/handlers/exception.py", line 125, in handle_uncaught_exception
    callback, param_dict = resolver.resolve_error_handler(500)
  File "/opt/openwisp2/env/lib/python3.5/site-packages/django/urls/resolvers.py", line 553, in resolve_error_handler
    callback = getattr(self.urlconf_module, 'handler%s' % view_type, None)
  File "/opt/openwisp2/env/lib/python3.5/site-packages/django/utils/functional.py", line 36, in __get__
    res = instance.__dict__[self.name] = self.func(instance)
  File "/opt/openwisp2/env/lib/python3.5/site-packages/django/urls/resolvers.py", line 533, in urlconf_module
    return import_module(self.urlconf_name)
  File "/opt/openwisp2/env/lib/python3.5/importlib/__init__.py", line 126, in import_module
    return _bootstrap._gcd_import(name[level:], package, level)
  File "<frozen importlib._bootstrap>", line 986, in _gcd_import
  File "<frozen importlib._bootstrap>", line 969, in _find_and_load
  File "<frozen importlib._bootstrap>", line 958, in _find_and_load_unlocked
  File "<frozen importlib._bootstrap>", line 673, in _load_unlocked
  File "<frozen importlib._bootstrap_external>", line 665, in exec_module
  File "<frozen importlib._bootstrap>", line 222, in _call_with_frames_removed
  File "./openwisp2/urls.py", line 19, in <module>
    url(r'^', include('openwisp_radius.urls', namespace='freeradius')),
  File "/opt/openwisp2/env/lib/python3.5/site-packages/django/urls/conf.py", line 34, in include
    urlconf_module = import_module(urlconf_module)
  File "/opt/openwisp2/env/lib/python3.5/importlib/__init__.py", line 126, in import_module
    return _bootstrap._gcd_import(name[level:], package, level)
  File "<frozen importlib._bootstrap>", line 986, in _gcd_import
  File "<frozen importlib._bootstrap>", line 969, in _find_and_load
  File "<frozen importlib._bootstrap>", line 958, in _find_and_load_unlocked
  File "<frozen importlib._bootstrap>", line 673, in _load_unlocked
  File "<frozen importlib._bootstrap_external>", line 665, in exec_module
  File "<frozen importlib._bootstrap>", line 222, in _call_with_frames_removed
  File "/opt/openwisp2/env/lib/python3.5/site-packages/openwisp_radius/urls.py", line 4, in <module>
    from .api import urls as api
  File "/opt/openwisp2/env/lib/python3.5/site-packages/openwisp_radius/api/urls.py", line 3, in <module>
    from . import views
  File "/opt/openwisp2/env/lib/python3.5/site-packages/openwisp_radius/api/views.py", line 10, in <module>
    from django_freeradius.api.views import AccountingView as BaseAccountingView
  File "/opt/openwisp2/env/lib/python3.5/site-packages/django_freeradius/api/views.py", line 15, in <module>
    from .serializers import RadiusAccountingSerializer, RadiusBatchSerializer, RadiusPostAuthSerializer
  File "/opt/openwisp2/env/lib/python3.5/site-packages/django_freeradius/api/serializers.py", line 7, in <module>
    RadiusPostAuth = swapper.load_model('django_freeradius', 'RadiusPostAuth')
  File "/opt/openwisp2/env/lib/python3.5/site-packages/swapper/__init__.py", line 94, in load_model
    "Could not find {name}!".format(name=join(app_label, model))
django.core.exceptions.ImproperlyConfigured: Could not find django_freeradius.RadiusPostAuth!

During handling of the above exception, another exception occurred:

Traceback (most recent call last):
  File "/opt/openwisp2/env/lib/python3.5/site-packages/django/core/handlers/exception.py", line 35, in inner
    response = get_response(request)
  File "/opt/openwisp2/env/lib/python3.5/site-packages/django/utils/deprecation.py", line 95, in __call__
    response = self.get_response(request)
  File "/opt/openwisp2/env/lib/python3.5/site-packages/django/core/handlers/exception.py", line 37, in inner
    response = response_for_exception(request, exc)
  File "/opt/openwisp2/env/lib/python3.5/site-packages/django/core/handlers/exception.py", line 87, in response_for_exception
    response = handle_uncaught_exception(request, get_resolver(get_urlconf()), sys.exc_info())
  File "/opt/openwisp2/env/lib/python3.5/site-packages/django/core/handlers/exception.py", line 125, in handle_uncaught_exception
    callback, param_dict = resolver.resolve_error_handler(500)
  File "/opt/openwisp2/env/lib/python3.5/site-packages/django/urls/resolvers.py", line 553, in resolve_error_handler
    callback = getattr(self.urlconf_module, 'handler%s' % view_type, None)
  File "/opt/openwisp2/env/lib/python3.5/site-packages/django/utils/functional.py", line 36, in __get__
    res = instance.__dict__[self.name] = self.func(instance)
  File "/opt/openwisp2/env/lib/python3.5/site-packages/django/urls/resolvers.py", line 533, in urlconf_module
    return import_module(self.urlconf_name)
  File "/opt/openwisp2/env/lib/python3.5/importlib/__init__.py", line 126, in import_module
    return _bootstrap._gcd_import(name[level:], package, level)
  File "<frozen importlib._bootstrap>", line 986, in _gcd_import
  File "<frozen importlib._bootstrap>", line 969, in _find_and_load
  File "<frozen importlib._bootstrap>", line 958, in _find_and_load_unlocked
  File "<frozen importlib._bootstrap>", line 673, in _load_unlocked
  File "<frozen importlib._bootstrap_external>", line 665, in exec_module
  File "<frozen importlib._bootstrap>", line 222, in _call_with_frames_removed
  File "./openwisp2/urls.py", line 19, in <module>
    url(r'^', include('openwisp_radius.urls', namespace='freeradius')),
  File "/opt/openwisp2/env/lib/python3.5/site-packages/django/urls/conf.py", line 34, in include
    urlconf_module = import_module(urlconf_module)
  File "/opt/openwisp2/env/lib/python3.5/importlib/__init__.py", line 126, in import_module
    return _bootstrap._gcd_import(name[level:], package, level)
  File "<frozen importlib._bootstrap>", line 986, in _gcd_import
  File "<frozen importlib._bootstrap>", line 969, in _find_and_load
  File "<frozen importlib._bootstrap>", line 958, in _find_and_load_unlocked
  File "<frozen importlib._bootstrap>", line 673, in _load_unlocked
  File "<frozen importlib._bootstrap_external>", line 665, in exec_module
  File "<frozen importlib._bootstrap>", line 222, in _call_with_frames_removed
  File "/opt/openwisp2/env/lib/python3.5/site-packages/openwisp_radius/urls.py", line 4, in <module>
    from .api import urls as api
  File "/opt/openwisp2/env/lib/python3.5/site-packages/openwisp_radius/api/urls.py", line 3, in <module>
    from . import views
  File "/opt/openwisp2/env/lib/python3.5/site-packages/openwisp_radius/api/views.py", line 10, in <module>
    from django_freeradius.api.views import AccountingView as BaseAccountingView
  File "/opt/openwisp2/env/lib/python3.5/site-packages/django_freeradius/api/views.py", line 15, in <module>
    from .serializers import RadiusAccountingSerializer, RadiusBatchSerializer, RadiusPostAuthSerializer
  File "/opt/openwisp2/env/lib/python3.5/site-packages/django_freeradius/api/serializers.py", line 7, in <module>
    RadiusPostAuth = swapper.load_model('django_freeradius', 'RadiusPostAuth')
  File "/opt/openwisp2/env/lib/python3.5/site-packages/swapper/__init__.py", line 94, in load_model
    "Could not find {name}!".format(name=join(app_label, model))
django.core.exceptions.ImproperlyConfigured: Could not find django_freeradius.RadiusPostAuth!

During handling of the above exception, another exception occurred:

Traceback (most recent call last):
  File "/opt/openwisp2/env/lib/python3.5/site-packages/django/core/handlers/exception.py", line 35, in inner
    response = get_response(request)
  File "/opt/openwisp2/env/lib/python3.5/site-packages/django/utils/deprecation.py", line 95, in __call__
    response = self.get_response(request)
  File "/opt/openwisp2/env/lib/python3.5/site-packages/django/core/handlers/exception.py", line 37, in inner
    response = response_for_exception(request, exc)
  File "/opt/openwisp2/env/lib/python3.5/site-packages/django/core/handlers/exception.py", line 87, in response_for_exception
    response = handle_uncaught_exception(request, get_resolver(get_urlconf()), sys.exc_info())
  File "/opt/openwisp2/env/lib/python3.5/site-packages/django/core/handlers/exception.py", line 125, in handle_uncaught_exception
    callback, param_dict = resolver.resolve_error_handler(500)
  File "/opt/openwisp2/env/lib/python3.5/site-packages/django/urls/resolvers.py", line 553, in resolve_error_handler
    callback = getattr(self.urlconf_module, 'handler%s' % view_type, None)
  File "/opt/openwisp2/env/lib/python3.5/site-packages/django/utils/functional.py", line 36, in __get__
    res = instance.__dict__[self.name] = self.func(instance)
  File "/opt/openwisp2/env/lib/python3.5/site-packages/django/urls/resolvers.py", line 533, in urlconf_module
    return import_module(self.urlconf_name)
  File "/opt/openwisp2/env/lib/python3.5/importlib/__init__.py", line 126, in import_module
    return _bootstrap._gcd_import(name[level:], package, level)
  File "<frozen importlib._bootstrap>", line 986, in _gcd_import
  File "<frozen importlib._bootstrap>", line 969, in _find_and_load
  File "<frozen importlib._bootstrap>", line 958, in _find_and_load_unlocked
  File "<frozen importlib._bootstrap>", line 673, in _load_unlocked
  File "<frozen importlib._bootstrap_external>", line 665, in exec_module
  File "<frozen importlib._bootstrap>", line 222, in _call_with_frames_removed
  File "./openwisp2/urls.py", line 19, in <module>
    url(r'^', include('openwisp_radius.urls', namespace='freeradius')),
  File "/opt/openwisp2/env/lib/python3.5/site-packages/django/urls/conf.py", line 34, in include
    urlconf_module = import_module(urlconf_module)
  File "/opt/openwisp2/env/lib/python3.5/importlib/__init__.py", line 126, in import_module
    return _bootstrap._gcd_import(name[level:], package, level)
  File "<frozen importlib._bootstrap>", line 986, in _gcd_import
  File "<frozen importlib._bootstrap>", line 969, in _find_and_load
  File "<frozen importlib._bootstrap>", line 958, in _find_and_load_unlocked
  File "<frozen importlib._bootstrap>", line 673, in _load_unlocked
  File "<frozen importlib._bootstrap_external>", line 665, in exec_module
  File "<frozen importlib._bootstrap>", line 222, in _call_with_frames_removed
  File "/opt/openwisp2/env/lib/python3.5/site-packages/openwisp_radius/urls.py", line 4, in <module>
    from .api import urls as api
  File "/opt/openwisp2/env/lib/python3.5/site-packages/openwisp_radius/api/urls.py", line 3, in <module>
    from . import views
  File "/opt/openwisp2/env/lib/python3.5/site-packages/openwisp_radius/api/views.py", line 10, in <module>
    from django_freeradius.api.views import AccountingView as BaseAccountingView
  File "/opt/openwisp2/env/lib/python3.5/site-packages/django_freeradius/api/views.py", line 15, in <module>
    from .serializers import RadiusAccountingSerializer, RadiusBatchSerializer, RadiusPostAuthSerializer
  File "/opt/openwisp2/env/lib/python3.5/site-packages/django_freeradius/api/serializers.py", line 7, in <module>
    RadiusPostAuth = swapper.load_model('django_freeradius', 'RadiusPostAuth')
  File "/opt/openwisp2/env/lib/python3.5/site-packages/swapper/__init__.py", line 94, in load_model
    "Could not find {name}!".format(name=join(app_label, model))
django.core.exceptions.ImproperlyConfigured: Could not find django_freeradius.RadiusPostAuth!


[ERROR 2019-08-12 14:04:58,818] module: exception, process: 15327, thread: 140303547352832
Internal Server Error: /admin/
Traceback (most recent call last):
  File "/opt/openwisp2/env/lib/python3.5/site-packages/django/core/handlers/exception.py", line 35, in inner
    response = get_response(request)
  File "/opt/openwisp2/env/lib/python3.5/site-packages/django/core/handlers/base.py", line 113, in _get_response
    resolver_match = resolver.resolve(request.path_info)
  File "/opt/openwisp2/env/lib/python3.5/site-packages/django/urls/resolvers.py", line 498, in resolve
    for pattern in self.url_patterns:
  File "/opt/openwisp2/env/lib/python3.5/site-packages/django/utils/functional.py", line 36, in __get__
    res = instance.__dict__[self.name] = self.func(instance)
  File "/opt/openwisp2/env/lib/python3.5/site-packages/django/urls/resolvers.py", line 540, in url_patterns
    patterns = getattr(self.urlconf_module, "urlpatterns", self.urlconf_module)
  File "/opt/openwisp2/env/lib/python3.5/site-packages/django/utils/functional.py", line 36, in __get__
    res = instance.__dict__[self.name] = self.func(instance)
  File "/opt/openwisp2/env/lib/python3.5/site-packages/django/urls/resolvers.py", line 533, in urlconf_module
    return import_module(self.urlconf_name)
  File "/opt/openwisp2/env/lib/python3.5/importlib/__init__.py", line 126, in import_module
    return _bootstrap._gcd_import(name[level:], package, level)
  File "<frozen importlib._bootstrap>", line 986, in _gcd_import
  File "<frozen importlib._bootstrap>", line 969, in _find_and_load
  File "<frozen importlib._bootstrap>", line 958, in _find_and_load_unlocked
  File "<frozen importlib._bootstrap>", line 673, in _load_unlocked
  File "<frozen importlib._bootstrap_external>", line 665, in exec_module
  File "<frozen importlib._bootstrap>", line 222, in _call_with_frames_removed
  File "./openwisp2/urls.py", line 19, in <module>
    url(r'^', include('openwisp_radius.urls', namespace='freeradius')),
  File "/opt/openwisp2/env/lib/python3.5/site-packages/django/urls/conf.py", line 34, in include
    urlconf_module = import_module(urlconf_module)
  File "/opt/openwisp2/env/lib/python3.5/importlib/__init__.py", line 126, in import_module
    return _bootstrap._gcd_import(name[level:], package, level)
  File "<frozen importlib._bootstrap>", line 986, in _gcd_import
  File "<frozen importlib._bootstrap>", line 969, in _find_and_load
  File "<frozen importlib._bootstrap>", line 958, in _find_and_load_unlocked
  File "<frozen importlib._bootstrap>", line 673, in _load_unlocked
  File "<frozen importlib._bootstrap_external>", line 665, in exec_module
  File "<frozen importlib._bootstrap>", line 222, in _call_with_frames_removed
  File "/opt/openwisp2/env/lib/python3.5/site-packages/openwisp_radius/urls.py", line 4, in <module>
    from .api import urls as api
  File "/opt/openwisp2/env/lib/python3.5/site-packages/openwisp_radius/api/urls.py", line 3, in <module>
    from . import views
  File "/opt/openwisp2/env/lib/python3.5/site-packages/openwisp_radius/api/views.py", line 10, in <module>
    from django_freeradius.api.views import AccountingView as BaseAccountingView
  File "/opt/openwisp2/env/lib/python3.5/site-packages/django_freeradius/api/views.py", line 15, in <module>
    from .serializers import RadiusAccountingSerializer, RadiusBatchSerializer, RadiusPostAuthSerializer
  File "/opt/openwisp2/env/lib/python3.5/site-packages/django_freeradius/api/serializers.py", line 7, in <module>
    RadiusPostAuth = swapper.load_model('django_freeradius', 'RadiusPostAuth')
  File "/opt/openwisp2/env/lib/python3.5/site-packages/swapper/__init__.py", line 94, in load_model
    "Could not find {name}!".format(name=join(app_label, model))
django.core.exceptions.ImproperlyConfigured: Could not find django_freeradius.RadiusPostAuth!

During handling of the above exception, another exception occurred:

Traceback (most recent call last):
  File "/opt/openwisp2/env/lib/python3.5/site-packages/django/core/handlers/exception.py", line 35, in inner
    response = get_response(request)
  File "/opt/openwisp2/env/lib/python3.5/site-packages/django/utils/deprecation.py", line 95, in __call__
    response = self.get_response(request)
  File "/opt/openwisp2/env/lib/python3.5/site-packages/django/core/handlers/exception.py", line 37, in inner
    response = response_for_exception(request, exc)
  File "/opt/openwisp2/env/lib/python3.5/site-packages/django/core/handlers/exception.py", line 87, in response_for_exception
    response = handle_uncaught_exception(request, get_resolver(get_urlconf()), sys.exc_info())
  File "/opt/openwisp2/env/lib/python3.5/site-packages/django/core/handlers/exception.py", line 125, in handle_uncaught_exception
    callback, param_dict = resolver.resolve_error_handler(500)
  File "/opt/openwisp2/env/lib/python3.5/site-packages/django/urls/resolvers.py", line 553, in resolve_error_handler
    callback = getattr(self.urlconf_module, 'handler%s' % view_type, None)
  File "/opt/openwisp2/env/lib/python3.5/site-packages/django/utils/functional.py", line 36, in __get__
    res = instance.__dict__[self.name] = self.func(instance)
  File "/opt/openwisp2/env/lib/python3.5/site-packages/django/urls/resolvers.py", line 533, in urlconf_module
    return import_module(self.urlconf_name)
  File "/opt/openwisp2/env/lib/python3.5/importlib/__init__.py", line 126, in import_module
    return _bootstrap._gcd_import(name[level:], package, level)
  File "<frozen importlib._bootstrap>", line 986, in _gcd_import
  File "<frozen importlib._bootstrap>", line 969, in _find_and_load
  File "<frozen importlib._bootstrap>", line 958, in _find_and_load_unlocked
  File "<frozen importlib._bootstrap>", line 673, in _load_unlocked
  File "<frozen importlib._bootstrap_external>", line 665, in exec_module
  File "<frozen importlib._bootstrap>", line 222, in _call_with_frames_removed
  File "./openwisp2/urls.py", line 19, in <module>
    url(r'^', include('openwisp_radius.urls', namespace='freeradius')),
  File "/opt/openwisp2/env/lib/python3.5/site-packages/django/urls/conf.py", line 34, in include
    urlconf_module = import_module(urlconf_module)
  File "/opt/openwisp2/env/lib/python3.5/importlib/__init__.py", line 126, in import_module
    return _bootstrap._gcd_import(name[level:], package, level)
  File "<frozen importlib._bootstrap>", line 986, in _gcd_import
  File "<frozen importlib._bootstrap>", line 969, in _find_and_load
  File "<frozen importlib._bootstrap>", line 958, in _find_and_load_unlocked
  File "<frozen importlib._bootstrap>", line 673, in _load_unlocked
  File "<frozen importlib._bootstrap_external>", line 665, in exec_module
  File "<frozen importlib._bootstrap>", line 222, in _call_with_frames_removed
  File "/opt/openwisp2/env/lib/python3.5/site-packages/openwisp_radius/urls.py", line 4, in <module>
    from .api import urls as api
  File "/opt/openwisp2/env/lib/python3.5/site-packages/openwisp_radius/api/urls.py", line 3, in <module>
    from . import views
  File "/opt/openwisp2/env/lib/python3.5/site-packages/openwisp_radius/api/views.py", line 10, in <module>
    from django_freeradius.api.views import AccountingView as BaseAccountingView
  File "/opt/openwisp2/env/lib/python3.5/site-packages/django_freeradius/api/views.py", line 15, in <module>
    from .serializers import RadiusAccountingSerializer, RadiusBatchSerializer, RadiusPostAuthSerializer
  File "/opt/openwisp2/env/lib/python3.5/site-packages/django_freeradius/api/serializers.py", line 7, in <module>
    RadiusPostAuth = swapper.load_model('django_freeradius', 'RadiusPostAuth')
  File "/opt/openwisp2/env/lib/python3.5/site-packages/swapper/__init__.py", line 94, in load_model
    "Could not find {name}!".format(name=join(app_label, model))
django.core.exceptions.ImproperlyConfigured: Could not find django_freeradius.RadiusPostAuth!

During handling of the above exception, another exception occurred:

Traceback (most recent call last):
  File "/opt/openwisp2/env/lib/python3.5/site-packages/django/core/handlers/exception.py", line 35, in inner
    response = get_response(request)
  File "/opt/openwisp2/env/lib/python3.5/site-packages/django/utils/deprecation.py", line 95, in __call__
    response = self.get_response(request)
  File "/opt/openwisp2/env/lib/python3.5/site-packages/django/core/handlers/exception.py", line 37, in inner
    response = response_for_exception(request, exc)
  File "/opt/openwisp2/env/lib/python3.5/site-packages/django/core/handlers/exception.py", line 87, in response_for_exception
    response = handle_uncaught_exception(request, get_resolver(get_urlconf()), sys.exc_info())
  File "/opt/openwisp2/env/lib/python3.5/site-packages/django/core/handlers/exception.py", line 125, in handle_uncaught_exception
    callback, param_dict = resolver.resolve_error_handler(500)
  File "/opt/openwisp2/env/lib/python3.5/site-packages/django/urls/resolvers.py", line 553, in resolve_error_handler
    callback = getattr(self.urlconf_module, 'handler%s' % view_type, None)
  File "/opt/openwisp2/env/lib/python3.5/site-packages/django/utils/functional.py", line 36, in __get__
    res = instance.__dict__[self.name] = self.func(instance)
  File "/opt/openwisp2/env/lib/python3.5/site-packages/django/urls/resolvers.py", line 533, in urlconf_module
    return import_module(self.urlconf_name)
  File "/opt/openwisp2/env/lib/python3.5/importlib/__init__.py", line 126, in import_module
    return _bootstrap._gcd_import(name[level:], package, level)
  File "<frozen importlib._bootstrap>", line 986, in _gcd_import
  File "<frozen importlib._bootstrap>", line 969, in _find_and_load
  File "<frozen importlib._bootstrap>", line 958, in _find_and_load_unlocked
  File "<frozen importlib._bootstrap>", line 673, in _load_unlocked
  File "<frozen importlib._bootstrap_external>", line 665, in exec_module
  File "<frozen importlib._bootstrap>", line 222, in _call_with_frames_removed
  File "./openwisp2/urls.py", line 19, in <module>
    url(r'^', include('openwisp_radius.urls', namespace='freeradius')),
  File "/opt/openwisp2/env/lib/python3.5/site-packages/django/urls/conf.py", line 34, in include
    urlconf_module = import_module(urlconf_module)
  File "/opt/openwisp2/env/lib/python3.5/importlib/__init__.py", line 126, in import_module
    return _bootstrap._gcd_import(name[level:], package, level)
  File "<frozen importlib._bootstrap>", line 986, in _gcd_import
  File "<frozen importlib._bootstrap>", line 969, in _find_and_load
  File "<frozen importlib._bootstrap>", line 958, in _find_and_load_unlocked
  File "<frozen importlib._bootstrap>", line 673, in _load_unlocked
  File "<frozen importlib._bootstrap_external>", line 665, in exec_module
  File "<frozen importlib._bootstrap>", line 222, in _call_with_frames_removed
  File "/opt/openwisp2/env/lib/python3.5/site-packages/openwisp_radius/urls.py", line 4, in <module>
    from .api import urls as api
  File "/opt/openwisp2/env/lib/python3.5/site-packages/openwisp_radius/api/urls.py", line 3, in <module>
    from . import views
  File "/opt/openwisp2/env/lib/python3.5/site-packages/openwisp_radius/api/views.py", line 10, in <module>
    from django_freeradius.api.views import AccountingView as BaseAccountingView
  File "/opt/openwisp2/env/lib/python3.5/site-packages/django_freeradius/api/views.py", line 15, in <module>
    from .serializers import RadiusAccountingSerializer, RadiusBatchSerializer, RadiusPostAuthSerializer
  File "/opt/openwisp2/env/lib/python3.5/site-packages/django_freeradius/api/serializers.py", line 7, in <module>
    RadiusPostAuth = swapper.load_model('django_freeradius', 'RadiusPostAuth')
  File "/opt/openwisp2/env/lib/python3.5/site-packages/swapper/__init__.py", line 94, in load_model
    "Could not find {name}!".format(name=join(app_label, model))
django.core.exceptions.ImproperlyConfigured: Could not find django_freeradius.RadiusPostAuth!

During handling of the above exception, another exception occurred:

Traceback (most recent call last):
  File "/opt/openwisp2/env/lib/python3.5/site-packages/django/core/handlers/exception.py", line 35, in inner
    response = get_response(request)
  File "/opt/openwisp2/env/lib/python3.5/site-packages/django/utils/deprecation.py", line 95, in __call__
    response = self.get_response(request)
  File "/opt/openwisp2/env/lib/python3.5/site-packages/django/core/handlers/exception.py", line 37, in inner
    response = response_for_exception(request, exc)
  File "/opt/openwisp2/env/lib/python3.5/site-packages/django/core/handlers/exception.py", line 87, in response_for_exception
    response = handle_uncaught_exception(request, get_resolver(get_urlconf()), sys.exc_info())
  File "/opt/openwisp2/env/lib/python3.5/site-packages/django/core/handlers/exception.py", line 125, in handle_uncaught_exception
    callback, param_dict = resolver.resolve_error_handler(500)
  File "/opt/openwisp2/env/lib/python3.5/site-packages/django/urls/resolvers.py", line 553, in resolve_error_handler
    callback = getattr(self.urlconf_module, 'handler%s' % view_type, None)
  File "/opt/openwisp2/env/lib/python3.5/site-packages/django/utils/functional.py", line 36, in __get__
    res = instance.__dict__[self.name] = self.func(instance)
  File "/opt/openwisp2/env/lib/python3.5/site-packages/django/urls/resolvers.py", line 533, in urlconf_module
    return import_module(self.urlconf_name)
  File "/opt/openwisp2/env/lib/python3.5/importlib/__init__.py", line 126, in import_module
    return _bootstrap._gcd_import(name[level:], package, level)
  File "<frozen importlib._bootstrap>", line 986, in _gcd_import
  File "<frozen importlib._bootstrap>", line 969, in _find_and_load
  File "<frozen importlib._bootstrap>", line 958, in _find_and_load_unlocked
  File "<frozen importlib._bootstrap>", line 673, in _load_unlocked
  File "<frozen importlib._bootstrap_external>", line 665, in exec_module
  File "<frozen importlib._bootstrap>", line 222, in _call_with_frames_removed
  File "./openwisp2/urls.py", line 19, in <module>
    url(r'^', include('openwisp_radius.urls', namespace='freeradius')),
  File "/opt/openwisp2/env/lib/python3.5/site-packages/django/urls/conf.py", line 34, in include
    urlconf_module = import_module(urlconf_module)
  File "/opt/openwisp2/env/lib/python3.5/importlib/__init__.py", line 126, in import_module
    return _bootstrap._gcd_import(name[level:], package, level)
  File "<frozen importlib._bootstrap>", line 986, in _gcd_import
  File "<frozen importlib._bootstrap>", line 969, in _find_and_load
  File "<frozen importlib._bootstrap>", line 958, in _find_and_load_unlocked
  File "<frozen importlib._bootstrap>", line 673, in _load_unlocked
  File "<frozen importlib._bootstrap_external>", line 665, in exec_module
  File "<frozen importlib._bootstrap>", line 222, in _call_with_frames_removed
  File "/opt/openwisp2/env/lib/python3.5/site-packages/openwisp_radius/urls.py", line 4, in <module>
    from .api import urls as api
  File "/opt/openwisp2/env/lib/python3.5/site-packages/openwisp_radius/api/urls.py", line 3, in <module>
    from . import views
  File "/opt/openwisp2/env/lib/python3.5/site-packages/openwisp_radius/api/views.py", line 10, in <module>
    from django_freeradius.api.views import AccountingView as BaseAccountingView
  File "/opt/openwisp2/env/lib/python3.5/site-packages/django_freeradius/api/views.py", line 15, in <module>
    from .serializers import RadiusAccountingSerializer, RadiusBatchSerializer, RadiusPostAuthSerializer
  File "/opt/openwisp2/env/lib/python3.5/site-packages/django_freeradius/api/serializers.py", line 7, in <module>
    RadiusPostAuth = swapper.load_model('django_freeradius', 'RadiusPostAuth')
  File "/opt/openwisp2/env/lib/python3.5/site-packages/swapper/__init__.py", line 94, in load_model
    "Could not find {name}!".format(name=join(app_label, model))
django.core.exceptions.ImproperlyConfigured: Could not find django_freeradius.RadiusPostAuth!

During handling of the above exception, another exception occurred:

Traceback (most recent call last):
  File "/opt/openwisp2/env/lib/python3.5/site-packages/django/core/handlers/exception.py", line 35, in inner
    response = get_response(request)
  File "/opt/openwisp2/env/lib/python3.5/site-packages/django/utils/deprecation.py", line 95, in __call__
    response = self.get_response(request)
  File "/opt/openwisp2/env/lib/python3.5/site-packages/django/core/handlers/exception.py", line 37, in inner
    response = response_for_exception(request, exc)
  File "/opt/openwisp2/env/lib/python3.5/site-packages/django/core/handlers/exception.py", line 87, in response_for_exception
    response = handle_uncaught_exception(request, get_resolver(get_urlconf()), sys.exc_info())
  File "/opt/openwisp2/env/lib/python3.5/site-packages/django/core/handlers/exception.py", line 125, in handle_uncaught_exception
    callback, param_dict = resolver.resolve_error_handler(500)
  File "/opt/openwisp2/env/lib/python3.5/site-packages/django/urls/resolvers.py", line 553, in resolve_error_handler
    callback = getattr(self.urlconf_module, 'handler%s' % view_type, None)
  File "/opt/openwisp2/env/lib/python3.5/site-packages/django/utils/functional.py", line 36, in __get__
    res = instance.__dict__[self.name] = self.func(instance)
  File "/opt/openwisp2/env/lib/python3.5/site-packages/django/urls/resolvers.py", line 533, in urlconf_module
    return import_module(self.urlconf_name)
  File "/opt/openwisp2/env/lib/python3.5/importlib/__init__.py", line 126, in import_module
    return _bootstrap._gcd_import(name[level:], package, level)
  File "<frozen importlib._bootstrap>", line 986, in _gcd_import
  File "<frozen importlib._bootstrap>", line 969, in _find_and_load
  File "<frozen importlib._bootstrap>", line 958, in _find_and_load_unlocked
  File "<frozen importlib._bootstrap>", line 673, in _load_unlocked
  File "<frozen importlib._bootstrap_external>", line 665, in exec_module
  File "<frozen importlib._bootstrap>", line 222, in _call_with_frames_removed
  File "./openwisp2/urls.py", line 19, in <module>
    url(r'^', include('openwisp_radius.urls', namespace='freeradius')),
  File "/opt/openwisp2/env/lib/python3.5/site-packages/django/urls/conf.py", line 34, in include
    urlconf_module = import_module(urlconf_module)
  File "/opt/openwisp2/env/lib/python3.5/importlib/__init__.py", line 126, in import_module
    return _bootstrap._gcd_import(name[level:], package, level)
  File "<frozen importlib._bootstrap>", line 986, in _gcd_import
  File "<frozen importlib._bootstrap>", line 969, in _find_and_load
  File "<frozen importlib._bootstrap>", line 958, in _find_and_load_unlocked
  File "<frozen importlib._bootstrap>", line 673, in _load_unlocked
  File "<frozen importlib._bootstrap_external>", line 665, in exec_module
  File "<frozen importlib._bootstrap>", line 222, in _call_with_frames_removed
  File "/opt/openwisp2/env/lib/python3.5/site-packages/openwisp_radius/urls.py", line 4, in <module>
    from .api import urls as api
  File "/opt/openwisp2/env/lib/python3.5/site-packages/openwisp_radius/api/urls.py", line 3, in <module>
    from . import views
  File "/opt/openwisp2/env/lib/python3.5/site-packages/openwisp_radius/api/views.py", line 10, in <module>
    from django_freeradius.api.views import AccountingView as BaseAccountingView
  File "/opt/openwisp2/env/lib/python3.5/site-packages/django_freeradius/api/views.py", line 15, in <module>
    from .serializers import RadiusAccountingSerializer, RadiusBatchSerializer, RadiusPostAuthSerializer
  File "/opt/openwisp2/env/lib/python3.5/site-packages/django_freeradius/api/serializers.py", line 7, in <module>
    RadiusPostAuth = swapper.load_model('django_freeradius', 'RadiusPostAuth')
  File "/opt/openwisp2/env/lib/python3.5/site-packages/swapper/__init__.py", line 94, in load_model
    "Could not find {name}!".format(name=join(app_label, model))
django.core.exceptions.ImproperlyConfigured: Could not find django_freeradius.RadiusPostAuth!

During handling of the above exception, another exception occurred:

Traceback (most recent call last):
  File "/opt/openwisp2/env/lib/python3.5/site-packages/django/core/handlers/exception.py", line 35, in inner
    response = get_response(request)
  File "/opt/openwisp2/env/lib/python3.5/site-packages/django/utils/deprecation.py", line 95, in __call__
    response = self.get_response(request)
  File "/opt/openwisp2/env/lib/python3.5/site-packages/django/core/handlers/exception.py", line 37, in inner
    response = response_for_exception(request, exc)
  File "/opt/openwisp2/env/lib/python3.5/site-packages/django/core/handlers/exception.py", line 87, in response_for_exception
    response = handle_uncaught_exception(request, get_resolver(get_urlconf()), sys.exc_info())
  File "/opt/openwisp2/env/lib/python3.5/site-packages/django/core/handlers/exception.py", line 125, in handle_uncaught_exception
    callback, param_dict = resolver.resolve_error_handler(500)
  File "/opt/openwisp2/env/lib/python3.5/site-packages/django/urls/resolvers.py", line 553, in resolve_error_handler
    callback = getattr(self.urlconf_module, 'handler%s' % view_type, None)
  File "/opt/openwisp2/env/lib/python3.5/site-packages/django/utils/functional.py", line 36, in __get__
    res = instance.__dict__[self.name] = self.func(instance)
  File "/opt/openwisp2/env/lib/python3.5/site-packages/django/urls/resolvers.py", line 533, in urlconf_module
    return import_module(self.urlconf_name)
  File "/opt/openwisp2/env/lib/python3.5/importlib/__init__.py", line 126, in import_module
    return _bootstrap._gcd_import(name[level:], package, level)
  File "<frozen importlib._bootstrap>", line 986, in _gcd_import
  File "<frozen importlib._bootstrap>", line 969, in _find_and_load
  File "<frozen importlib._bootstrap>", line 958, in _find_and_load_unlocked
  File "<frozen importlib._bootstrap>", line 673, in _load_unlocked
  File "<frozen importlib._bootstrap_external>", line 665, in exec_module
  File "<frozen importlib._bootstrap>", line 222, in _call_with_frames_removed
  File "./openwisp2/urls.py", line 19, in <module>
    url(r'^', include('openwisp_radius.urls', namespace='freeradius')),
  File "/opt/openwisp2/env/lib/python3.5/site-packages/django/urls/conf.py", line 34, in include
    urlconf_module = import_module(urlconf_module)
  File "/opt/openwisp2/env/lib/python3.5/importlib/__init__.py", line 126, in import_module
    return _bootstrap._gcd_import(name[level:], package, level)
  File "<frozen importlib._bootstrap>", line 986, in _gcd_import
  File "<frozen importlib._bootstrap>", line 969, in _find_and_load
  File "<frozen importlib._bootstrap>", line 958, in _find_and_load_unlocked
  File "<frozen importlib._bootstrap>", line 673, in _load_unlocked
  File "<frozen importlib._bootstrap_external>", line 665, in exec_module
  File "<frozen importlib._bootstrap>", line 222, in _call_with_frames_removed
  File "/opt/openwisp2/env/lib/python3.5/site-packages/openwisp_radius/urls.py", line 4, in <module>
    from .api import urls as api
  File "/opt/openwisp2/env/lib/python3.5/site-packages/openwisp_radius/api/urls.py", line 3, in <module>
    from . import views
  File "/opt/openwisp2/env/lib/python3.5/site-packages/openwisp_radius/api/views.py", line 10, in <module>
    from django_freeradius.api.views import AccountingView as BaseAccountingView
  File "/opt/openwisp2/env/lib/python3.5/site-packages/django_freeradius/api/views.py", line 15, in <module>
    from .serializers import RadiusAccountingSerializer, RadiusBatchSerializer, RadiusPostAuthSerializer
  File "/opt/openwisp2/env/lib/python3.5/site-packages/django_freeradius/api/serializers.py", line 7, in <module>
    RadiusPostAuth = swapper.load_model('django_freeradius', 'RadiusPostAuth')
  File "/opt/openwisp2/env/lib/python3.5/site-packages/swapper/__init__.py", line 94, in load_model
    "Could not find {name}!".format(name=join(app_label, model))
django.core.exceptions.ImproperlyConfigured: Could not find django_freeradius.RadiusPostAuth!

During handling of the above exception, another exception occurred:

Traceback (most recent call last):
  File "/opt/openwisp2/env/lib/python3.5/site-packages/django/core/handlers/exception.py", line 35, in inner
    response = get_response(request)
  File "/opt/openwisp2/env/lib/python3.5/site-packages/django/utils/deprecation.py", line 95, in __call__
    response = self.get_response(request)
  File "/opt/openwisp2/env/lib/python3.5/site-packages/django/core/handlers/exception.py", line 37, in inner
    response = response_for_exception(request, exc)
  File "/opt/openwisp2/env/lib/python3.5/site-packages/django/core/handlers/exception.py", line 87, in response_for_exception
    response = handle_uncaught_exception(request, get_resolver(get_urlconf()), sys.exc_info())
  File "/opt/openwisp2/env/lib/python3.5/site-packages/django/core/handlers/exception.py", line 125, in handle_uncaught_exception
    callback, param_dict = resolver.resolve_error_handler(500)
  File "/opt/openwisp2/env/lib/python3.5/site-packages/django/urls/resolvers.py", line 553, in resolve_error_handler
    callback = getattr(self.urlconf_module, 'handler%s' % view_type, None)
  File "/opt/openwisp2/env/lib/python3.5/site-packages/django/utils/functional.py", line 36, in __get__
    res = instance.__dict__[self.name] = self.func(instance)
  File "/opt/openwisp2/env/lib/python3.5/site-packages/django/urls/resolvers.py", line 533, in urlconf_module
    return import_module(self.urlconf_name)
  File "/opt/openwisp2/env/lib/python3.5/importlib/__init__.py", line 126, in import_module
    return _bootstrap._gcd_import(name[level:], package, level)
  File "<frozen importlib._bootstrap>", line 986, in _gcd_import
  File "<frozen importlib._bootstrap>", line 969, in _find_and_load
  File "<frozen importlib._bootstrap>", line 958, in _find_and_load_unlocked
  File "<frozen importlib._bootstrap>", line 673, in _load_unlocked
  File "<frozen importlib._bootstrap_external>", line 665, in exec_module
  File "<frozen importlib._bootstrap>", line 222, in _call_with_frames_removed
  File "./openwisp2/urls.py", line 19, in <module>
    url(r'^', include('openwisp_radius.urls', namespace='freeradius')),
  File "/opt/openwisp2/env/lib/python3.5/site-packages/django/urls/conf.py", line 34, in include
    urlconf_module = import_module(urlconf_module)
  File "/opt/openwisp2/env/lib/python3.5/importlib/__init__.py", line 126, in import_module
    return _bootstrap._gcd_import(name[level:], package, level)
  File "<frozen importlib._bootstrap>", line 986, in _gcd_import
  File "<frozen importlib._bootstrap>", line 969, in _find_and_load
  File "<frozen importlib._bootstrap>", line 958, in _find_and_load_unlocked
  File "<frozen importlib._bootstrap>", line 673, in _load_unlocked
  File "<frozen importlib._bootstrap_external>", line 665, in exec_module
  File "<frozen importlib._bootstrap>", line 222, in _call_with_frames_removed
  File "/opt/openwisp2/env/lib/python3.5/site-packages/openwisp_radius/urls.py", line 4, in <module>
    from .api import urls as api
  File "/opt/openwisp2/env/lib/python3.5/site-packages/openwisp_radius/api/urls.py", line 3, in <module>
    from . import views
  File "/opt/openwisp2/env/lib/python3.5/site-packages/openwisp_radius/api/views.py", line 10, in <module>
    from django_freeradius.api.views import AccountingView as BaseAccountingView
  File "/opt/openwisp2/env/lib/python3.5/site-packages/django_freeradius/api/views.py", line 15, in <module>
    from .serializers import RadiusAccountingSerializer, RadiusBatchSerializer, RadiusPostAuthSerializer
  File "/opt/openwisp2/env/lib/python3.5/site-packages/django_freeradius/api/serializers.py", line 7, in <module>
    RadiusPostAuth = swapper.load_model('django_freeradius', 'RadiusPostAuth')
  File "/opt/openwisp2/env/lib/python3.5/site-packages/swapper/__init__.py", line 94, in load_model
    "Could not find {name}!".format(name=join(app_label, model))
django.core.exceptions.ImproperlyConfigured: Could not find django_freeradius.RadiusPostAuth!


[ERROR 2019-08-12 14:04:59,502] module: exception, process: 15327, thread: 140303052732160
Internal Server Error: /admin/logout/
Traceback (most recent call last):
  File "/opt/openwisp2/env/lib/python3.5/site-packages/django/core/handlers/exception.py", line 35, in inner
    response = get_response(request)
  File "/opt/openwisp2/env/lib/python3.5/site-packages/django/core/handlers/base.py", line 113, in _get_response
    resolver_match = resolver.resolve(request.path_info)
  File "/opt/openwisp2/env/lib/python3.5/site-packages/django/urls/resolvers.py", line 498, in resolve
    for pattern in self.url_patterns:
  File "/opt/openwisp2/env/lib/python3.5/site-packages/django/utils/functional.py", line 36, in __get__
    res = instance.__dict__[self.name] = self.func(instance)
  File "/opt/openwisp2/env/lib/python3.5/site-packages/django/urls/resolvers.py", line 540, in url_patterns
    patterns = getattr(self.urlconf_module, "urlpatterns", self.urlconf_module)
  File "/opt/openwisp2/env/lib/python3.5/site-packages/django/utils/functional.py", line 36, in __get__
    res = instance.__dict__[self.name] = self.func(instance)
  File "/opt/openwisp2/env/lib/python3.5/site-packages/django/urls/resolvers.py", line 533, in urlconf_module
    return import_module(self.urlconf_name)
  File "/opt/openwisp2/env/lib/python3.5/importlib/__init__.py", line 126, in import_module
    return _bootstrap._gcd_import(name[level:], package, level)
  File "<frozen importlib._bootstrap>", line 986, in _gcd_import
  File "<frozen importlib._bootstrap>", line 969, in _find_and_load
  File "<frozen importlib._bootstrap>", line 958, in _find_and_load_unlocked
  File "<frozen importlib._bootstrap>", line 673, in _load_unlocked
  File "<frozen importlib._bootstrap_external>", line 665, in exec_module
  File "<frozen importlib._bootstrap>", line 222, in _call_with_frames_removed
  File "./openwisp2/urls.py", line 19, in <module>
    url(r'^', include('openwisp_radius.urls', namespace='freeradius')),
  File "/opt/openwisp2/env/lib/python3.5/site-packages/django/urls/conf.py", line 34, in include
    urlconf_module = import_module(urlconf_module)
  File "/opt/openwisp2/env/lib/python3.5/importlib/__init__.py", line 126, in import_module
    return _bootstrap._gcd_import(name[level:], package, level)
  File "<frozen importlib._bootstrap>", line 986, in _gcd_import
  File "<frozen importlib._bootstrap>", line 969, in _find_and_load
  File "<frozen importlib._bootstrap>", line 958, in _find_and_load_unlocked
  File "<frozen importlib._bootstrap>", line 673, in _load_unlocked
  File "<frozen importlib._bootstrap_external>", line 665, in exec_module
  File "<frozen importlib._bootstrap>", line 222, in _call_with_frames_removed
  File "/opt/openwisp2/env/lib/python3.5/site-packages/openwisp_radius/urls.py", line 4, in <module>
    from .api import urls as api
  File "/opt/openwisp2/env/lib/python3.5/site-packages/openwisp_radius/api/urls.py", line 3, in <module>
    from . import views
  File "/opt/openwisp2/env/lib/python3.5/site-packages/openwisp_radius/api/views.py", line 10, in <module>
    from django_freeradius.api.views import AccountingView as BaseAccountingView
  File "/opt/openwisp2/env/lib/python3.5/site-packages/django_freeradius/api/views.py", line 15, in <module>
    from .serializers import RadiusAccountingSerializer, RadiusBatchSerializer, RadiusPostAuthSerializer
  File "/opt/openwisp2/env/lib/python3.5/site-packages/django_freeradius/api/serializers.py", line 7, in <module>
    RadiusPostAuth = swapper.load_model('django_freeradius', 'RadiusPostAuth')
  File "/opt/openwisp2/env/lib/python3.5/site-packages/swapper/__init__.py", line 94, in load_model
    "Could not find {name}!".format(name=join(app_label, model))
django.core.exceptions.ImproperlyConfigured: Could not find django_freeradius.RadiusPostAuth!
